Workbook

Sheet Регистрация
A1: Межмуниципальные соревнования по всестилевому каратэ "Первый старт" 27 сентября 2025 г.
A2: Вид спорта: ВСЕСТИЛЕВОЕ КАРАТЭ (номер-код вида спорта - 0900001411Я)
A3: Женщины 18 + ОК-двоеборье | G3: г. Санкт-Петербург | L3: 27 сентября 2025
A4: вид программы | G4: место проведения соревнований | L4: Дата проведения соревнований
A5: П Р О Т О К О Л Р Е Г И С Т Р А Ц И И
A6: М 18+ ОК-двоеборье | D6: =DCOUNTA(D7:D71,1,D7:D71) -> 6
A7: № | B7: № жреб. | C7: пол | D7: Фамилия | E7: Имя | F7: Отчество | G7: Дата рождения | H7: Полных лет | I7: Разряд, звание | J7: Точный вес | K7: Вид программы | L7: Команда | M7: Регион | N7: Тренер | O7: Занятое место
A8: 1 | B8: 4 | C8: ж | D8: Шайдулина | E8: Алина | F8: Викторовна | G8: 38223 | H8: 21 | I8: б/р | K8: ОК-АБС | L8: Политех | M8: Санкт-Петербург | N8: Орлова Е.С. | O8: 3
A9: 2 | B9: 1 | C9: ж | D9: Сугралиева | E9: Арина | F9: Маратовна | G9: 38890 | H9: 19 | I9: б/р | J9: 2 спорт. | K9: ОК-АБС | L9: Политех | M9: Санкт-Петербург | N9: Орлова Е.С. | O9: 4
A10: 3 | B10: 5 | C10: ж | D10: Носкова | E10: Александра | F10: Сергеевна | G10: 37335 | H10: 23 | I10: б/р | K10: ОК-АБС | L10: Политех | M10: Санкт-Петербург | N10: Орлова Е.С. | O10: 1
A11: 4 | B11: 3 | C11: ж | D11: Паранина | E11: Полина | F11: Николаевна | G11: 38159 | H11: 21 | I11: б/р | K11: ОК-АБС | L11: Политех | M11: Санкт-Петербург | N11: Орлова Е.С. | O11: 5-6
A12: 5 | B12: 2 | C12: ж | D12: Хохлова | E12: Элина | F12: Александровна | G12: 38764 | H12: 19 | I12: 1 спорт | K12: ОК-АБС | L12: WSKF | M12: Санкт-Петербург | N12: Пименов .Г | O12: 2
A13: 6 | B13: 6 | C13: ж | D13: Павлова | E13: Мария | F13: Олеговна | G13: 38910 | H13: 19 | I13: б/р | J13: КМС | K13: ОК-АБС | L13: Политех | M13: Санкт-Петербург | N13: Орлова Е.С. | O13: 5-6
A14: 7 | B14: 7
A15: 8 | B15: 8
A16: 9 | B16: 9
A17: 10 | B17: 10
A18: 11 | B18: 11
A19: 12 | B19: 12
A20: 13 | B20: 13
A21: 14 | B21: 14
A22: 15 | B22: 15
A23: 16 | B23: 16
A24: 17 | B24: 17
A25: 18 | B25: 18
... A70: 63 | B70: 63
A71: 64
F73: Главный судья: | N73: Цыльев В.А. С1К
F74: Главный секретерь: | N74: Орлова Е.С 3 К

Sheet 3
A1: =Регистрация!A1 -> Межмуниципальные соревнования по всестилевому каратэ "Первый старт" 27 сентября 2025 г.
A3: =Регистрация!A2 -> Вид спорта: ВСЕСТИЛЕВОЕ КАРАТЭ (номер-код вида спорта - 0900001411Я)
A5: =Регистрация!A3 -> Женщины 18 + ОК-двоеборье | D5: =Регистрация!G3 -> г. Санкт-Петербург | I5: =Регистрация!L3 -> 27 сентября 2025 | J5: =Регистрация!N3 -> 0
A7: П Р О Т О К О Л Х О Д А С О Р Е В Н О В А Н И Й
A10: 1 | B10: =IF(Регистрация!$D$6<A10," ",CONCATENATE(VLOOKUP(A10,Регистрация!$B$7:$N$39,3,FALSE)," ",VLOOKUP(A10,Регистрация!$B$7:$N$39,4,FALSE)," ","(",VLOOKUP(A10,Регистрация!$B$7:$N$39,11,FALSE),")")) -> Сугралиева Арина (Политех)
G12: =IF(F12=0," ",CONCATENATE(VLOOKUP(F12,Регистрация!$B$7:$N$39,3,FALSE)," ",VLOOKUP(F12,Регистрация!$B$7:$N$39,4,FALSE)))
A14: 3 | B14: =IF(Регистрация!$D$6<A14," ",CONCATENATE(VLOOKUP(A14,Регистрация!$B$7:$N$39,3,FALSE)," ",VLOOKUP(A14,Регистрация!$B$7:$N$39,4,FALSE)," ","(",VLOOKUP(A14,Регистрация!$B$7:$N$39,11,FALSE),")")) -> Паранина Полина (Политех)
A17: 2 | B17: =IF(Регистрация!$D$6<A17," ",CONCATENATE(VLOOKUP(A17,Регистрация!$B$7:$N$39,3,FALSE)," ",VLOOKUP(A17,Регистрация!$B$7:$N$39,4,FALSE)," ","(",VLOOKUP(A17,Регистрация!$B$7:$N$39,11,FALSE),")")) -> Хохлова Элина (WSKF)
G19: =IF(F19=0," ",CONCATENATE(VLOOKUP(F19,Регистрация!$B$7:$N$39,3,FALSE)," ",VLOOKUP(F19,Регистрация!$B$7:$N$39,4,FALSE)))
A21: 3 | B21: =IF(Регистрация!$D$6<A21," ",CONCATENATE(VLOOKUP(A21,Регистрация!$B$7:$N$39,3,FALSE)," ",VLOOKUP(A21,Регистрация!$B$7:$N$39,4,FALSE)," ","(",VLOOKUP(A21,Регистрация!$B$7:$N$39,11,FALSE),")")) -> Паранина Полина (Политех)
A24: 1 | B24: =IF(Регистрация!$D$6<A24," ",CONCATENATE(VLOOKUP(A24,Регистрация!$B$7:$N$39,3,FALSE)," ",VLOOKUP(A24,Регистрация!$B$7:$N$39,4,FALSE)," ","(",VLOOKUP(A24,Регистрация!$B$7:$N$39,11,FALSE),")")) -> Сугралиева Арина (Политех)
G26: =IF(F26=0," ",CONCATENATE(VLOOKUP(F26,Регистрация!$B$7:$N$39,3,FALSE)," ",VLOOKUP(F26,Регистрация!$B$7:$N$39,4,FALSE)))
A28: 2 | B28: =IF(Регистрация!$D$6<A28," ",CONCATENATE(VLOOKUP(A28,Регистрация!$B$7:$N$39,3,FALSE)," ",VLOOKUP(A28,Регистрация!$B$7:$N$39,4,FALSE)," ","(",VLOOKUP(A28,Регистрация!$B$7:$N$39,11,FALSE),")")) -> Хохлова Элина (WSKF)
B33: Результаты
B34: Место | C34: Фамилия Имя Отчество (Регион)
B35: 1 | C35: =IF(A35=0," ",CONCATENATE(VLOOKUP(A35,Регистрация!$B$7:$N$39,3,FALSE)," ",VLOOKUP(A35,Регистрация!$B$7:$N$39,4,FALSE)," ",VLOOKUP(A35,Регистрация!$B$7:$N$39,5,FALSE)," ","(",VLOOKUP(A35,Регистрация!$B$7:$N$39,11,FALSE),")"))
B36: 2 | C36: =IF(A36=0," ",CONCATENATE(VLOOKUP(A36,Регистрация!$B$7:$N$39,3,FALSE)," ",VLOOKUP(A36,Регистрация!$B$7:$N$39,4,FALSE)," ",VLOOKUP(A36,Регистрация!$B$7:$N$39,5,FALSE)," ","(",VLOOKUP(A36,Регистрация!$B$7:$N$39,11,FALSE),")"))
B37: 3 | C37: =IF(A37=0," ",CONCATENATE(VLOOKUP(A37,Регистрация!$B$7:$N$39,3,FALSE)," ",VLOOKUP(A37,Регистрация!$B$7:$N$39,4,FALSE)," ",VLOOKUP(A37,Регистрация!$B$7:$N$39,5,FALSE)," ","(",VLOOKUP(A37,Регистрация!$B$7:$N$39,11,FALSE),")"))
B38: 4 | C38: =IF(A38=0," ",CONCATENATE(VLOOKUP(A38,Регистрация!$B$7:$N$39,3,FALSE)," ",VLOOKUP(A38,Регистрация!$B$7:$N$39,4,FALSE)," ",VLOOKUP(A38,Регистрация!$B$7:$N$39,5,FALSE)," ","(",VLOOKUP(A38,Регистрация!$B$7:$N$39,11,FALSE),")"))
A40: Главный судья: | H40: =Регистрация!N73 -> Цыльев В.А. С1К
A42: Главный секретарь: | H42: =Регистрация!N74 -> Орлова Е.С 3 К

Sheet 4
A1: =Регистрация!A1 -> Межмуниципальные соревнования по всестилевому каратэ "Первый старт" 27 сентября 2025 г.
A3: =Регистрация!A2 -> Вид спорта: ВСЕСТИЛЕВОЕ КАРАТЭ (номер-код вида спорта - 0900001411Я)
A5: =Регистрация!A3 -> Женщины 18 + ОК-двоеборье | D5: =Регистрация!G3 -> г. Санкт-Петербург | I5: =Регистрация!L3 -> 27 сентября 2025 | J5: =Регистрация!N3 -> 0
A7: П Р О Т О К О Л Х О Д А С О Р Е В Н О В А Н И Й
A10: 1 | B10: =IF(Регистрация!$D$6<A10," ",CONCATENATE(VLOOKUP(A10,Регистрация!$B$7:$N$39,3,FALSE)," ",VLOOKUP(A10,Регистрация!$B$7:$N$39,4,FALSE)," ","(",VLOOKUP(A10,Регистрация!$B$7:$N$39,11,FALSE),")")) -> Сугралиева Арина (Политех)
F12: 1 | G12: =IF(F12=0," ",CONCATENATE(VLOOKUP(F12,Регистрация!$B$7:$N$39,3,FALSE)," ",VLOOKUP(F12,Регистрация!$B$7:$N$39,4,FALSE))) -> Сугралиева Арина
A14: 3 | B14: =IF(Регистрация!$D$6<A14," ",CONCATENATE(VLOOKUP(A14,Регистрация!$B$7:$N$39,3,FALSE)," ",VLOOKUP(A14,Регистрация!$B$7:$N$39,4,FALSE)," ","(",VLOOKUP(A14,Регистрация!$B$7:$N$39,11,FALSE),")")) -> Паранина Полина (Политех)
I15: =IF(H15=0," ",CONCATENATE(VLOOKUP(H15,Регистрация!$B$7:$N$39,3,FALSE)," ",VLOOKUP(H15,Регистрация!$B$7:$N$39,4,FALSE)))
A17: 2 | B17: =IF(Регистрация!$D$6<A17," ",CONCATENATE(VLOOKUP(A17,Регистрация!$B$7:$N$39,3,FALSE)," ",VLOOKUP(A17,Регистрация!$B$7:$N$39,4,FALSE)," ","(",VLOOKUP(A17,Регистрация!$B$7:$N$39,11,FALSE),")")) -> Хохлова Элина (WSKF)
F19: 2 | G19: =IF(F19=0," ",CONCATENATE(VLOOKUP(F19,Регистрация!$B$7:$N$39,3,FALSE)," ",VLOOKUP(F19,Регистрация!$B$7:$N$39,4,FALSE))) -> Хохлова Элина
A21: 4 | B21: =IF(Регистрация!$D$6<A21," ",CONCATENATE(VLOOKUP(A21,Регистрация!$B$7:$N$39,3,FALSE)," ",VLOOKUP(A21,Регистрация!$B$7:$N$39,4,FALSE)," ","(",VLOOKUP(A21,Регистрация!$B$7:$N$39,11,FALSE),")")) -> Шайдулина Алина (Политех)
F23: поединок за 3-е место
F25: =IF(F12=0,0,IF(A10=F12,A14,A10)) -> 3 | G25: =IF(F25=0," ",CONCATENATE(VLOOKUP(F25,Регистрация!$B$7:$N$39,3,FALSE)," ",VLOOKUP(F25,Регистрация!$B$7:$N$39,4,FALSE))) -> Паранина Полина
I26: =IF(H26=0," ",CONCATENATE(VLOOKUP(H26,Регистрация!$B$7:$N$39,3,FALSE)," ",VLOOKUP(H26,Регистрация!$B$7:$N$39,4,FALSE)))
F27: =IF(F19=0,0,IF(A17=F19,A21,A17)) -> 4 | G27: =IF(F27=0," ",CONCATENATE(VLOOKUP(F27,Регистрация!$B$7:$N$39,3,FALSE)," ",VLOOKUP(F27,Регистрация!$B$7:$N$39,4,FALSE))) -> Шайдулина Алина
B29: Результаты
B30: Место | C30: Фамилия Имя Отчество (Регион)
A31: =H15 -> 0 | B31: 1 | C31: =IF(A31=0," ",CONCATENATE(VLOOKUP(A31,Регистрация!$B$7:$N$39,3,FALSE)," ",VLOOKUP(A31,Регистрация!$B$7:$N$39,4,FALSE)," ",VLOOKUP(A31,Регистрация!$B$7:$N$39,5,FALSE)," ","(",VLOOKUP(A31,Регистрация!$B$7:$N$39,11,FALSE),")"))
A32: =IF(H15=0,0,IF(H15=F12,F19,F12)) -> 0 | B32: 2 | C32: =IF(A32=0," ",CONCATENATE(VLOOKUP(A32,Регистрация!$B$7:$N$39,3,FALSE)," ",VLOOKUP(A32,Регистрация!$B$7:$N$39,4,FALSE)," ",VLOOKUP(A32,Регистрация!$B$7:$N$39,5,FALSE)," ","(",VLOOKUP(A32,Регистрация!$B$7:$N$39,11,FALSE),")"))
A33: =H26 -> 0 | B33: 3 | C33: =IF(A33=0," ",CONCATENATE(VLOOKUP(A33,Регистрация!$B$7:$N$39,3,FALSE)," ",VLOOKUP(A33,Регистрация!$B$7:$N$39,4,FALSE)," ",VLOOKUP(A33,Регистрация!$B$7:$N$39,5,FALSE)," ","(",VLOOKUP(A33,Регистрация!$B$7:$N$39,11,FALSE),")"))
A34: =IF(H26=0,0,IF(H26=F25,F27,F25)) -> 0 | B34: 4 | C34: =IF(A34=0," ",CONCATENATE(VLOOKUP(A34,Регистрация!$B$7:$N$39,3,FALSE)," ",VLOOKUP(A34,Регистрация!$B$7:$N$39,4,FALSE)," ",VLOOKUP(A34,Регистрация!$B$7:$N$39,5,FALSE)," ","(",VLOOKUP(A34,Регистрация!$B$7:$N$39,11,FALSE),")"))
A36: Главный судья: | H36: =Регистрация!N73 -> Цыльев В.А. С1К
A38: Главный секретарь: | H38: =Регистрация!N74 -> Орлова Е.С 3 К

Sheet 5
A1: =Регистрация!A1 -> Межмуниципальные соревнования по всестилевому каратэ "Первый старт" 27 сентября 2025 г.
A3: =Регистрация!A2 -> Вид спорта: ВСЕСТИЛЕВОЕ КАРАТЭ (номер-код вида спорта - 0900001411Я)
A5: =Регистрация!A3 -> Женщины 18 + ОК-двоеборье | D5: =Регистрация!G3 -> г. Санкт-Петербург | I5: =Регистрация!L3 -> 27 сентября 2025 | J5: =Регистрация!N3 -> 0
A7: П Р О Т О К О Л Х О Д А С О Р Е В Н О В А Н И Й
A10: 1 | B10: =IF(Регистрация!$D$6<A10," ",CONCATENATE(VLOOKUP(A10,Регистрация!$B$7:$N$39,3,FALSE)," ",VLOOKUP(A10,Регистрация!$B$7:$N$39,4,FALSE)," ","(",VLOOKUP(A10,Регистрация!$B$7:$N$39,11,FALSE),")")) -> Сугралиева Арина (Политех)
G12: =IF(F12=0," ",CONCATENATE(VLOOKUP(F12,Регистрация!$B$7:$N$39,3,FALSE)," ",VLOOKUP(F12,Регистрация!$B$7:$N$39,4,FALSE)))
A13: 3 | B13: =IF(Регистрация!$D$6<A13," ",CONCATENATE(VLOOKUP(A13,Регистрация!$B$7:$N$39,3,FALSE)," ",VLOOKUP(A13,Регистрация!$B$7:$N$39,4,FALSE)," ","(",VLOOKUP(A13,Регистрация!$B$7:$N$39,11,FALSE),")")) -> Паранина Полина (Политех)
E14: =IF(D14=0," ",CONCATENATE(VLOOKUP(D14,Регистрация!$B$7:$N$39,3,FALSE)," ",VLOOKUP(D14,Регистрация!$B$7:$N$39,4,FALSE)))
A15: 5 | B15: =IF(Регистрация!$D$6<A15," ",CONCATENATE(VLOOKUP(A15,Регистрация!$B$7:$N$39,3,FALSE)," ",VLOOKUP(A15,Регистрация!$B$7:$N$39,4,FALSE)," ","(",VLOOKUP(A15,Регистрация!$B$7:$N$39,11,FALSE),")")) -> Носкова Александра (Политех)
I16: =IF(H16=0," ",CONCATENATE(VLOOKUP(H16,Регистрация!$B$7:$N$39,3,FALSE)," ",VLOOKUP(H16,Регистрация!$B$7:$N$39,4,FALSE)))
A18: 2 | B18: =IF(Регистрация!$D$6<A18," ",CONCATENATE(VLOOKUP(A18,Регистрация!$B$7:$N$39,3,FALSE)," ",VLOOKUP(A18,Регистрация!$B$7:$N$39,4,FALSE)," ","(",VLOOKUP(A18,Регистрация!$B$7:$N$39,11,FALSE),")")) -> Хохлова Элина (WSKF)
G20: =IF(F20=0," ",CONCATENATE(VLOOKUP(F20,Регистрация!$B$7:$N$39,3,FALSE)," ",VLOOKUP(F20,Регистрация!$B$7:$N$39,4,FALSE)))
A22: 4 | B22: =IF(Регистрация!$D$6<A22," ",CONCATENATE(VLOOKUP(A22,Регистрация!$B$7:$N$39,3,FALSE)," ",VLOOKUP(A22,Регистрация!$B$7:$N$39,4,FALSE)," ","(",VLOOKUP(A22,Регистрация!$B$7:$N$39,11,FALSE),")")) -> Шайдулина Алина (Политех)
F24: поединок за 3-е место
F26: =IF(F12=0,0,IF(A10=F12,D14,A10)) -> 0 | G26: =IF(F26=0," ",CONCATENATE(VLOOKUP(F26,Регистрация!$B$7:$N$39,3,FALSE)," ",VLOOKUP(F26,Регистрация!$B$7:$N$39,4,FALSE)))
I27: =IF(H27=0," ",CONCATENATE(VLOOKUP(H27,Регистрация!$B$7:$N$39,3,FALSE)," ",VLOOKUP(H27,Регистрация!$B$7:$N$39,4,FALSE)))
F28: =IF(F20=0,0,IF(A18=F20,A22,A18)) -> 0 | G28: =IF(F28=0," ",CONCATENATE(VLOOKUP(F28,Регистрация!$B$7:$N$39,3,FALSE)," ",VLOOKUP(F28,Регистрация!$B$7:$N$39,4,FALSE)))
B30: Результаты
B31: Место | C31: Фамилия Имя Отчество (Регион)
A32: =H16 -> 0 | B32: 1 | C32: =IF(A32=0," ",CONCATENATE(VLOOKUP(A32,Регистрация!$B$7:$N$39,3,FALSE)," ",VLOOKUP(A32,Регистрация!$B$7:$N$39,4,FALSE)," ",VLOOKUP(A32,Регистрация!$B$7:$N$39,5,FALSE)," ","(",VLOOKUP(A32,Регистрация!$B$7:$N$39,11,FALSE),")"))
A33: =IF(H16=0,0,IF(H16=F12,F20,F12)) -> 0 | B33: 2 | C33: =IF(A33=0," ",CONCATENATE(VLOOKUP(A33,Регистрация!$B$7:$N$39,3,FALSE)," ",VLOOKUP(A33,Регистрация!$B$7:$N$39,4,FALSE)," ",VLOOKUP(A33,Регистрация!$B$7:$N$39,5,FALSE)," ","(",VLOOKUP(A33,Регистрация!$B$7:$N$39,11,FALSE),")"))
A34: =H27 -> 0 | B34: 3 | C34: =IF(A34=0," ",CONCATENATE(VLOOKUP(A34,Регистрация!$B$7:$N$39,3,FALSE)," ",VLOOKUP(A34,Регистрация!$B$7:$N$39,4,FALSE)," ",VLOOKUP(A34,Регистрация!$B$7:$N$39,5,FALSE)," ","(",VLOOKUP(A34,Регистрация!$B$7:$N$39,11,FALSE),")"))
A35: =IF(H27=0,0,IF(H27=F26,F28,F26)) -> 0 | B35: 4 | C35: =IF(A35=0," ",CONCATENATE(VLOOKUP(A35,Регистрация!$B$7:$N$39,3,FALSE)," ",VLOOKUP(A35,Регистрация!$B$7:$N$39,4,FALSE)," ",VLOOKUP(A35,Регистрация!$B$7:$N$39,5,FALSE)," ","(",VLOOKUP(A35,Регистрация!$B$7:$N$39,11,FALSE),")"))
A37: Главный судья: | H37: =Регистрация!N73 -> Цыльев В.А. С1К
A39: Главный секретарь: | H39: =Регистрация!N74 -> Орлова Е.С 3 К

Sheet 6
A1: =Регистрация!A1 -> Межмуниципальные соревнования по всестилевому каратэ "Первый старт" 27 сентября 2025 г.
A3: =Регистрация!A2 -> Вид спорта: ВСЕСТИЛЕВОЕ КАРАТЭ (номер-код вида спорта - 0900001411Я)
A5: =Регистрация!A3 -> Женщины 18 + ОК-двоеборье | D5: =Регистрация!G3 -> г. Санкт-Петербург | I5: =Регистрация!L3 -> 27 сентября 2025
A7: П Р О Т О К О Л Х О Д А С О Р Е В Н О В А Н И Й
A10: 1 | B10: =IF(Регистрация!$D$6<A10," ",CONCATENATE(VLOOKUP(A10,Регистрация!$B$7:$N$39,3,FALSE)," ",VLOOKUP(A10,Регистрация!$B$7:$N$39,4,FALSE)," ","(",VLOOKUP(A10,Регистрация!$B$7:$N$39,11,FALSE),")")) -> Сугралиева Арина (Политех)
F12: 5 | G12: =IF(F12=0," ",CONCATENATE(VLOOKUP(F12,Регистрация!$B$7:$N$39,3,FALSE)," ",VLOOKUP(F12,Регистрация!$B$7:$N$39,4,FALSE))) -> Носкова Александра
A13: 3 | B13: =IF(Регистрация!$D$6<A13," ",CONCATENATE(VLOOKUP(A13,Регистрация!$B$7:$N$39,3,FALSE)," ",VLOOKUP(A13,Регистрация!$B$7:$N$39,4,FALSE)," ","(",VLOOKUP(A13,Регистрация!$B$7:$N$39,11,FALSE),")")) -> Паранина Полина (Политех)
D14: 5 | E14: =IF(D14=0," ",CONCATENATE(VLOOKUP(D14,Регистрация!$B$7:$N$39,3,FALSE)," ",VLOOKUP(D14,Регистрация!$B$7:$N$39,4,FALSE))) -> Носкова Александра
A15: 5 | B15: =IF(Регистрация!$D$6<A15," ",CONCATENATE(VLOOKUP(A15,Регистрация!$B$7:$N$39,3,FALSE)," ",VLOOKUP(A15,Регистрация!$B$7:$N$39,4,FALSE)," ","(",VLOOKUP(A15,Регистрация!$B$7:$N$39,11,FALSE),")")) -> Носкова Александра (Политех)
H16: 5 | I16: =IF(H16=0," ",CONCATENATE(VLOOKUP(H16,Регистрация!$B$7:$N$39,3,FALSE)," ",VLOOKUP(H16,Регистрация!$B$7:$N$39,4,FALSE))) -> Носкова Александра
A18: 2 | B18: =IF(Регистрация!$D$6<A18," ",CONCATENATE(VLOOKUP(A18,Регистрация!$B$7:$N$39,3,FALSE)," ",VLOOKUP(A18,Регистрация!$B$7:$N$39,4,FALSE)," ","(",VLOOKUP(A18,Регистрация!$B$7:$N$39,11,FALSE),")")) -> Хохлова Элина (WSKF)
F20: 2 | G20: =IF(F20=0," ",CONCATENATE(VLOOKUP(F20,Регистрация!$B$7:$N$39,3,FALSE)," ",VLOOKUP(F20,Регистрация!$B$7:$N$39,4,FALSE))) -> Хохлова Элина
A21: 4 | B21: =IF(Регистрация!$D$6<A21," ",CONCATENATE(VLOOKUP(A21,Регистрация!$B$7:$N$39,3,FALSE)," ",VLOOKUP(A21,Регистрация!$B$7:$N$39,4,FALSE)," ","(",VLOOKUP(A21,Регистрация!$B$7:$N$39,11,FALSE),")")) -> Шайдулина Алина (Политех)
D22: 4 | E22: =IF(D22=0," ",CONCATENATE(VLOOKUP(D22,Регистрация!$B$7:$N$39,3,FALSE)," ",VLOOKUP(D22,Регистрация!$B$7:$N$39,4,FALSE))) -> Шайдулина Алина
A23: 6 | B23: =IF(Регистрация!$D$6<A23," ",CONCATENATE(VLOOKUP(A23,Регистрация!$B$7:$N$39,3,FALSE)," ",VLOOKUP(A23,Регистрация!$B$7:$N$39,4,FALSE)," ","(",VLOOKUP(A23,Регистрация!$B$7:$N$39,11,FALSE),")")) -> Павлова Мария (Политех)
F24: поединок за 3-е место
F26: =IF(F12=0,0,IF(F12=A10,D14,A10)) -> 1 | G26: =IF(F26=0," ",CONCATENATE(VLOOKUP(F26,Регистрация!$B$7:$N$39,3,FALSE)," ",VLOOKUP(F26,Регистрация!$B$7:$N$39,4,FALSE))) -> Сугралиева Арина
H27: 4 | I27: =IF(H27=0," ",CONCATENATE(VLOOKUP(H27,Регистрация!$B$7:$N$39,3,FALSE)," ",VLOOKUP(H27,Регистрация!$B$7:$N$39,4,FALSE))) -> Шайдулина Алина
F28: 4 | G28: =IF(F28=0," ",CONCATENATE(VLOOKUP(F28,Регистрация!$B$7:$N$39,3,FALSE)," ",VLOOKUP(F28,Регистрация!$B$7:$N$39,4,FALSE))) -> Шайдулина Алина
B30: Результаты
B31: Место | C31: Фамилия Имя Отчество (Команда)
A32: =H16 -> 5 | B32: 1 | C32: =IF(A32=0," ",CONCATENATE(VLOOKUP(A32,Регистрация!$B$7:$N$39,3,FALSE)," ",VLOOKUP(A32,Регистрация!$B$7:$N$39,4,FALSE)," ",VLOOKUP(A32,Регистрация!$B$7:$N$39,5,FALSE)," ","(",VLOOKUP(A32,Регистрация!$B$7:$N$39,11,FALSE),")")) -> Носкова Александра Сергеевна (Политех)
A33: =IF(H16=0,0,IF(H16=F12,F20,F12)) -> 2 | B33: 2 | C33: =IF(A33=0," ",CONCATENATE(VLOOKUP(A33,Регистрация!$B$7:$N$39,3,FALSE)," ",VLOOKUP(A33,Регистрация!$B$7:$N$39,4,FALSE)," ",VLOOKUP(A33,Регистрация!$B$7:$N$39,5,FALSE)," ","(",VLOOKUP(A33,Регистрация!$B$7:$N$39,11,FALSE),")")) -> Хохлова Элина Александровна (WSKF)
A34: =H27 -> 4 | B34: 3 | C34: =IF(A34=0," ",CONCATENATE(VLOOKUP(A34,Регистрация!$B$7:$N$39,3,FALSE)," ",VLOOKUP(A34,Регистрация!$B$7:$N$39,4,FALSE)," ",VLOOKUP(A34,Регистрация!$B$7:$N$39,5,FALSE)," ","(",VLOOKUP(A34,Регистрация!$B$7:$N$39,11,FALSE),")")) -> Шайдулина Алина Викторовна (Политех)
A35: =IF(H27=0,0,IF(H27=F26,F28,F26)) -> 1 | B35: 4 | C35: =IF(A35=0," ",CONCATENATE(VLOOKUP(A35,Регистрация!$B$7:$N$39,3,FALSE)," ",VLOOKUP(A35,Регистрация!$B$7:$N$39,4,FALSE)," ",VLOOKUP(A35,Регистрация!$B$7:$N$39,5,FALSE)," ","(",VLOOKUP(A35,Регистрация!$B$7:$N$39,11,FALSE),")")) -> Сугралиева Арина Маратовна (Политех)
A37: Главный судья: | H37: =Регистрация!N73 -> Цыльев В.А. С1К
A39: Главный секретарь: | H39: =Регистрация!N74 -> Орлова Е.С 3 К

Sheet 7
A1: =Регистрация!A1 -> Межмуниципальные соревнования по всестилевому каратэ "Первый старт" 27 сентября 2025 г.
A3: =Регистрация!A2 -> Вид спорта: ВСЕСТИЛЕВОЕ КАРАТЭ (номер-код вида спорта - 0900001411Я)
A5: =Регистрация!A3 -> Женщины 18 + ОК-двоеборье | D5: =Регистрация!G3 -> г. Санкт-Петербург | I5: =Регистрация!L3 -> 27 сентября 2025 | J5: =Регистрация!N3 -> 0
A7: П Р О Т О К О Л Х О Д А С О Р Е В Н О В А Н И Й
A10: 2 | B10: =IF(Регистрация!$D$6<A10," ",CONCATENATE(VLOOKUP(A10,Регистрация!$B$7:$N$39,3,FALSE)," ",VLOOKUP(A10,Регистрация!$B$7:$N$39,4,FALSE)," ","(",VLOOKUP(A10,Регистрация!$B$7:$N$39,11,FALSE),")")) -> Хохлова Элина (WSKF)
G12: =IF(F12=0," ",CONCATENATE(VLOOKUP(F12,Регистрация!$B$7:$N$39,3,FALSE)," ",VLOOKUP(F12,Регистрация!$B$7:$N$39,4,FALSE)))
A13: 4 | B13: =IF(Регистрация!$D$6<A13," ",CONCATENATE(VLOOKUP(A13,Регистрация!$B$7:$N$39,3,FALSE)," ",VLOOKUP(A13,Регистрация!$B$7:$N$39,4,FALSE)," ","(",VLOOKUP(A13,Регистрация!$B$7:$N$39,11,FALSE),")")) -> Шайдулина Алина (Политех)
E14: =IF(D14=0," ",CONCATENATE(VLOOKUP(D14,Регистрация!$B$7:$N$39,3,FALSE)," ",VLOOKUP(D14,Регистрация!$B$7:$N$39,4,FALSE)))
A15: 6 | B15: =IF(Регистрация!$D$6<A15," ",CONCATENATE(VLOOKUP(A15,Регистрация!$B$7:$N$39,3,FALSE)," ",VLOOKUP(A15,Регистрация!$B$7:$N$39,4,FALSE)," ","(",VLOOKUP(A15,Регистрация!$B$7:$N$39,11,FALSE),")")) -> Павлова Мария (Политех)
I16: =IF(H16=0," ",CONCATENATE(VLOOKUP(H16,Регистрация!$B$7:$N$39,3,FALSE)," ",VLOOKUP(H16,Регистрация!$B$7:$N$39,4,FALSE)))
A17: 1 | B17: =IF(Регистрация!$D$6<A17," ",CONCATENATE(VLOOKUP(A17,Регистрация!$B$7:$N$39,3,FALSE)," ",VLOOKUP(A17,Регистрация!$B$7:$N$39,4,FALSE)," ","(",VLOOKUP(A17,Регистрация!$B$7:$N$39,11,FALSE),")")) -> Сугралиева Арина (Политех)
E18: =IF(D18=0," ",CONCATENATE(VLOOKUP(D18,Регистрация!$B$7:$N$39,3,FALSE)," ",VLOOKUP(D18,Регистрация!$B$7:$N$39,4,FALSE)))
A19: 5 | B19: =IF(Регистрация!$D$6<A19," ",CONCATENATE(VLOOKUP(A19,Регистрация!$B$7:$N$39,3,FALSE)," ",VLOOKUP(A19,Регистрация!$B$7:$N$39,4,FALSE)," ","(",VLOOKUP(A19,Регистрация!$B$7:$N$39,11,FALSE),")")) -> Носкова Александра (Политех)
G20: =IF(F20=0," ",CONCATENATE(VLOOKUP(F20,Регистрация!$B$7:$N$39,3,FALSE)," ",VLOOKUP(F20,Регистрация!$B$7:$N$39,4,FALSE)))
A21: 3 | B21: =IF(Регистрация!$D$6<A21," ",CONCATENATE(VLOOKUP(A21,Регистрация!$B$7:$N$39,3,FALSE)," ",VLOOKUP(A21,Регистрация!$B$7:$N$39,4,FALSE)," ","(",VLOOKUP(A21,Регистрация!$B$7:$N$39,11,FALSE),")")) -> Паранина Полина (Политех)
E22: =IF(D22=0," ",CONCATENATE(VLOOKUP(D22,Регистрация!$B$7:$N$39,3,FALSE)," ",VLOOKUP(D22,Регистрация!$B$7:$N$39,4,FALSE)))
A23: 7 | B23: =IF(Регистрация!$D$6<A23," ",CONCATENATE(VLOOKUP(A23,Регистрация!$B$7:$N$39,3,FALSE)," ",VLOOKUP(A23,Регистрация!$B$7:$N$39,4,FALSE)," ","(",VLOOKUP(A23,Регистрация!$B$7:$N$39,11,FALSE),")"))
F24: поединок за 3-е место
F26: =IF(F12=0,0,IF(A10=F12,D14,A10)) -> 0 | G26: =IF(F26=0," ",CONCATENATE(VLOOKUP(F26,Регистрация!$B$7:$N$39,3,FALSE)," ",VLOOKUP(F26,Регистрация!$B$7:$N$39,4,FALSE)))
I27: =IF(H27=0," ",CONCATENATE(VLOOKUP(H27,Регистрация!$B$7:$N$39,3,FALSE)," ",VLOOKUP(H27,Регистрация!$B$7:$N$39,4,FALSE)))
F28: =IF(F20=0,0,IF(D18=F20,D22,D18)) -> 0 | G28: =IF(F28=0," ",CONCATENATE(VLOOKUP(F28,Регистрация!$B$7:$N$39,3,FALSE)," ",VLOOKUP(F28,Регистрация!$B$7:$N$39,4,FALSE)))
B30: Результаты
B31: Место | C31: Фамилия Имя Отчество (Регион)
A32: =H16 -> 0 | B32: 1 | C32: =IF(A32=0," ",CONCATENATE(VLOOKUP(A32,Регистрация!$B$7:$N$39,3,FALSE)," ",VLOOKUP(A32,Регистрация!$B$7:$N$39,4,FALSE)," ",VLOOKUP(A32,Регистрация!$B$7:$N$39,5,FALSE)," ","(",VLOOKUP(A32,Регистрация!$B$7:$N$39,11,FALSE),")"))
A33: =IF(H16=0,0,IF(H16=F12,F20,F12)) -> 0 | B33: 2 | C33: =IF(A33=0," ",CONCATENATE(VLOOKUP(A33,Регистрация!$B$7:$N$39,3,FALSE)," ",VLOOKUP(A33,Регистрация!$B$7:$N$39,4,FALSE)," ",VLOOKUP(A33,Регистрация!$B$7:$N$39,5,FALSE)," ","(",VLOOKUP(A33,Регистрация!$B$7:$N$39,11,FALSE),")"))
A34: =H27 -> 0 | B34: 3 | C34: =IF(A34=0," ",CONCATENATE(VLOOKUP(A34,Регистрация!$B$7:$N$39,3,FALSE)," ",VLOOKUP(A34,Регистрация!$B$7:$N$39,4,FALSE)," ",VLOOKUP(A34,Регистрация!$B$7:$N$39,5,FALSE)," ","(",VLOOKUP(A34,Регистрация!$B$7:$N$39,11,FALSE),")"))
A35: =IF(H27=0,0,IF(H27=F26,F28,F26)) -> 0 | B35: 4 | C35: =IF(A35=0," ",CONCATENATE(VLOOKUP(A35,Регистрация!$B$7:$N$39,3,FALSE)," ",VLOOKUP(A35,Регистрация!$B$7:$N$39,4,FALSE)," ",VLOOKUP(A35,Регистрация!$B$7:$N$39,5,FALSE)," ","(",VLOOKUP(A35,Регистрация!$B$7:$N$39,11,FALSE),")"))
A37: Главный судья: | H37: =Регистрация!N73 -> Цыльев В.А. С1К
A39: Главный секретарь: | H39: =Регистрация!N74 -> Орлова Е.С 3 К

Sheet 8
A1: =Регистрация!A1 -> Межмуниципальные соревнования по всестилевому каратэ "Первый старт" 27 сентября 2025 г.
A3: =Регистрация!A2 -> Вид спорта: ВСЕСТИЛЕВОЕ КАРАТЭ (номер-код вида спорта - 0900001411Я)
A5: =Регистрация!A3 -> Женщины 18 + ОК-двоеборье | D5: =Регистрация!G3 -> г. Санкт-Петербург | I5: =Регистрация!L3 -> 27 сентября 2025 | J5: =Регистрация!N3 -> 0
A7: П Р О Т О К О Л Х О Д А С О Р Е В Н О В А Н И Й
A9: 1 | B9: =IF(Регистрация!$D$6<A9," ",CONCATENATE(VLOOKUP(A9,Регистрация!$B$7:$N$39,3,FALSE)," ",VLOOKUP(A9,Регистрация!$B$7:$N$39,4,FALSE)," ","(",VLOOKUP(A9,Регистрация!$B$7:$N$39,11,FALSE),")")) -> Сугралиева Арина (Политех)
E10: =IF(D10=0," ",CONCATENATE(VLOOKUP(D10,Регистрация!$B$7:$N$39,3,FALSE)," ",VLOOKUP(D10,Регистрация!$B$7:$N$39,4,FALSE)))
A11: 5 | B11: =IF(Регистрация!$D$6<A11," ",CONCATENATE(VLOOKUP(A11,Регистрация!$B$7:$N$39,3,FALSE)," ",VLOOKUP(A11,Регистрация!$B$7:$N$39,4,FALSE)," ","(",VLOOKUP(A11,Регистрация!$B$7:$N$39,11,FALSE),")")) -> Носкова Александра (Политех)
G12: =IF(F12=0," ",CONCATENATE(VLOOKUP(F12,Регистрация!$B$7:$N$39,3,FALSE)," ",VLOOKUP(F12,Регистрация!$B$7:$N$39,4,FALSE)))
A13: 3 | B13: =IF(Регистрация!$D$6<A13," ",CONCATENATE(VLOOKUP(A13,Регистрация!$B$7:$N$39,3,FALSE)," ",VLOOKUP(A13,Регистрация!$B$7:$N$39,4,FALSE)," ","(",VLOOKUP(A13,Регистрация!$B$7:$N$39,11,FALSE),")")) -> Паранина Полина (Политех)
E14: =IF(D14=0," ",CONCATENATE(VLOOKUP(D14,Регистрация!$B$7:$N$39,3,FALSE)," ",VLOOKUP(D14,Регистрация!$B$7:$N$39,4,FALSE)))
A15: 7 | B15: =IF(Регистрация!$D$6<A15," ",CONCATENATE(VLOOKUP(A15,Регистрация!$B$7:$N$39,3,FALSE)," ",VLOOKUP(A15,Регистрация!$B$7:$N$39,4,FALSE)," ","(",VLOOKUP(A15,Регистрация!$B$7:$N$39,11,FALSE),")"))
I16: =IF(H16=0," ",CONCATENATE(VLOOKUP(H16,Регистрация!$B$7:$N$39,3,FALSE)," ",VLOOKUP(H16,Регистрация!$B$7:$N$39,4,FALSE)))
A17: 2 | B17: =IF(Регистрация!$D$6<A17," ",CONCATENATE(VLOOKUP(A17,Регистрация!$B$7:$N$39,3,FALSE)," ",VLOOKUP(A17,Регистрация!$B$7:$N$39,4,FALSE)," ","(",VLOOKUP(A17,Регистрация!$B$7:$N$39,11,FALSE),")")) -> Хохлова Элина (WSKF)
E18: =IF(D18=0," ",CONCATENATE(VLOOKUP(D18,Регистрация!$B$7:$N$39,3,FALSE)," ",VLOOKUP(D18,Регистрация!$B$7:$N$39,4,FALSE)))
A19: 6 | B19: =IF(Регистрация!$D$6<A19," ",CONCATENATE(VLOOKUP(A19,Регистрация!$B$7:$N$39,3,FALSE)," ",VLOOKUP(A19,Регистрация!$B$7:$N$39,4,FALSE)," ","(",VLOOKUP(A19,Регистрация!$B$7:$N$39,11,FALSE),")")) -> Павлова Мария (Политех)
G20: =IF(F20=0," ",CONCATENATE(VLOOKUP(F20,Регистрация!$B$7:$N$39,3,FALSE)," ",VLOOKUP(F20,Регистрация!$B$7:$N$39,4,FALSE)))
A21: 4 | B21: =IF(Регистрация!$D$6<A21," ",CONCATENATE(VLOOKUP(A21,Регистрация!$B$7:$N$39,3,FALSE)," ",VLOOKUP(A21,Регистрация!$B$7:$N$39,4,FALSE)," ","(",VLOOKUP(A21,Регистрация!$B$7:$N$39,11,FALSE),")")) -> Шайдулина Алина (Политех)
E22: =IF(D22=0," ",CONCATENATE(VLOOKUP(D22,Регистрация!$B$7:$N$39,3,FALSE)," ",VLOOKUP(D22,Регистрация!$B$7:$N$39,4,FALSE)))
A23: 8 | B23: =IF(Регистрация!$D$6<A23," ",CONCATENATE(VLOOKUP(A23,Регистрация!$B$7:$N$39,3,FALSE)," ",VLOOKUP(A23,Регистрация!$B$7:$N$39,4,FALSE)," ","(",VLOOKUP(A23,Регистрация!$B$7:$N$39,11,FALSE),")"))
F24: поединок за 3-е место
F26: =IF(F12=0,0,IF(D10=F12,D14,D10)) -> 0 | G26: =IF(F26=0," ",CONCATENATE(VLOOKUP(F26,Регистрация!$B$7:$N$39,3,FALSE)," ",VLOOKUP(F26,Регистрация!$B$7:$N$39,4,FALSE)))
I27: =IF(H27=0," ",CONCATENATE(VLOOKUP(H27,Регистрация!$B$7:$N$39,3,FALSE)," ",VLOOKUP(H27,Регистрация!$B$7:$N$39,4,FALSE)))
F28: =IF(F20=0,0,IF(D18=F20,D22,D18)) -> 0 | G28: =IF(F28=0," ",CONCATENATE(VLOOKUP(F28,Регистрация!$B$7:$N$39,3,FALSE)," ",VLOOKUP(F28,Регистрация!$B$7:$N$39,4,FALSE)))
B30: Результаты
B31: Место | C31: Фамилия Имя Отчество (Регион)
A32: =H16 -> 0 | B32: 1 | C32: =IF(A32=0," ",CONCATENATE(VLOOKUP(A32,Регистрация!$B$7:$N$39,3,FALSE)," ",VLOOKUP(A32,Регистрация!$B$7:$N$39,4,FALSE)," ",VLOOKUP(A32,Регистрация!$B$7:$N$39,5,FALSE)," ","(",VLOOKUP(A32,Регистрация!$B$7:$N$39,11,FALSE),")"))
A33: =IF(H16=0,0,IF(H16=F12,F20,F12)) -> 0 | B33: 2 | C33: =IF(A33=0," ",CONCATENATE(VLOOKUP(A33,Регистрация!$B$7:$N$39,3,FALSE)," ",VLOOKUP(A33,Регистрация!$B$7:$N$39,4,FALSE)," ",VLOOKUP(A33,Регистрация!$B$7:$N$39,5,FALSE)," ","(",VLOOKUP(A33,Регистрация!$B$7:$N$39,11,FALSE),")"))
A34: =H27 -> 0 | B34: 3 | C34: =IF(A34=0," ",CONCATENATE(VLOOKUP(A34,Регистрация!$B$7:$N$39,3,FALSE)," ",VLOOKUP(A34,Регистрация!$B$7:$N$39,4,FALSE)," ",VLOOKUP(A34,Регистрация!$B$7:$N$39,5,FALSE)," ","(",VLOOKUP(A34,Регистрация!$B$7:$N$39,11,FALSE),")"))
A35: =IF(H27=0,0,IF(H27=F26,F28,F26)) -> 0 | B35: 4 | C35: =IF(A35=0," ",CONCATENATE(VLOOKUP(A35,Регистрация!$B$7:$N$39,3,FALSE)," ",VLOOKUP(A35,Регистрация!$B$7:$N$39,4,FALSE)," ",VLOOKUP(A35,Регистрация!$B$7:$N$39,5,FALSE)," ","(",VLOOKUP(A35,Регистрация!$B$7:$N$39,11,FALSE),")"))
A37: Главный судья: | H37: =Регистрация!N73 -> Цыльев В.А. С1К
A39: Главный секретарь: | H39: =Регистрация!N74 -> Орлова Е.С 3 К

Sheet 9
A1: =Регистрация!A1 -> Межмуниципальные соревнования по всестилевому каратэ "Первый старт" 27 сентября 2025 г.
A3: =Регистрация!A2 -> Вид спорта: ВСЕСТИЛЕВОЕ КАРАТЭ (номер-код вида спорта - 0900001411Я)
A5: =Регистрация!A3 -> Женщины 18 + ОК-двоеборье | D5: =Регистрация!G3 -> г. Санкт-Петербург | I5: =Регистрация!L3 -> 27 сентября 2025 | K5: =Регистрация!N3 -> 0
A7: П Р О Т О К О Л Х О Д А С О Р Е В Н О В А Н И Й
A9: 1 | B9: =IF(Регистрация!$D$6<A9," ",CONCATENATE(VLOOKUP(A9,Регистрация!$B$7:$N$39,3,FALSE)," ",VLOOKUP(A9,Регистрация!$B$7:$N$39,4,FALSE)," ","(",VLOOKUP(A9,Регистрация!$B$7:$N$39,11,FALSE),")")) -> Сугралиева Арина (Политех) | D9: =IF(Регистрация!$D$6<C9," ",CONCATENATE(VLOOKUP(C9,Регистрация!$B$7:$N$39,3,FALSE)," ",VLOOKUP(C9,Регистрация!$B$7:$N$39,4,FALSE)," ","(",VLOOKUP(C9,Регистрация!$B$7:$N$39,11,FALSE),")")) -> #N/A
G11: =IF(F11=0," ",CONCATENATE(VLOOKUP(F11,Регистрация!$B$7:$N$39,3,FALSE)," ",VLOOKUP(F11,Регистрация!$B$7:$N$39,4,FALSE)))
A12: 5 | B12: =IF(Регистрация!$D$6<A12," ",CONCATENATE(VLOOKUP(A12,Регистрация!$B$7:$N$39,3,FALSE)," ",VLOOKUP(A12,Регистрация!$B$7:$N$39,4,FALSE)," ","(",VLOOKUP(A12,Регистрация!$B$7:$N$39,11,FALSE),")")) -> Носкова Александра (Политех)
E13: =IF(D13=0," ",CONCATENATE(VLOOKUP(D13,Регистрация!$B$7:$N$39,3,FALSE)," ",VLOOKUP(D13,Регистрация!$B$7:$N$39,4,FALSE)))
A14: 9 | B14: =IF(Регистрация!$D$6<A14," ",CONCATENATE(VLOOKUP(A14,Регистрация!$B$7:$N$39,3,FALSE)," ",VLOOKUP(A14,Регистрация!$B$7:$N$39,4,FALSE)," ","(",VLOOKUP(A14,Регистрация!$B$7:$N$39,11,FALSE),")"))
I15: =IF(H15=0," ",CONCATENATE(VLOOKUP(H15,Регистрация!$B$7:$N$39,3,FALSE)," ",VLOOKUP(H15,Регистрация!$B$7:$N$39,4,FALSE)))
A17: 3 | B17: =IF(Регистрация!$D$6<A17," ",CONCATENATE(VLOOKUP(A17,Регистрация!$B$7:$N$39,3,FALSE)," ",VLOOKUP(A17,Регистрация!$B$7:$N$39,4,FALSE)," ","(",VLOOKUP(A17,Регистрация!$B$7:$N$39,11,FALSE),")")) -> Паранина Полина (Политех) | D17: =IF(Регистрация!$D$6<C17," ",CONCATENATE(VLOOKUP(C17,Регистрация!$B$7:$N$39,3,FALSE)," ",VLOOKUP(C17,Регистрация!$B$7:$N$39,4,FALSE)," ","(",VLOOKUP(C17,Регистрация!$B$7:$N$39,11,FALSE),")")) -> #N/A
G19: =IF(F19=0," ",CONCATENATE(VLOOKUP(F19,Регистрация!$B$7:$N$39,3,FALSE)," ",VLOOKUP(F19,Регистрация!$B$7:$N$39,4,FALSE)))
A21: 7 | B21: =IF(Регистрация!$D$6<A21," ",CONCATENATE(VLOOKUP(A21,Регистрация!$B$7:$N$39,3,FALSE)," ",VLOOKUP(A21,Регистрация!$B$7:$N$39,4,FALSE)," ","(",VLOOKUP(A21,Регистрация!$B$7:$N$39,11,FALSE),")")) | D21: =IF(Регистрация!$D$6<C21," ",CONCATENATE(VLOOKUP(C21,Регистрация!$B$7:$N$39,3,FALSE)," ",VLOOKUP(C21,Регистрация!$B$7:$N$39,4,FALSE)," ","(",VLOOKUP(C21,Регистрация!$B$7:$N$39,11,FALSE),")")) -> #N/A
K23: =IF(J23=0," ",CONCATENATE(VLOOKUP(J23,Регистрация!$B$7:$N$39,3,FALSE)," ",VLOOKUP(J23,Регистрация!$B$7:$N$39,4,FALSE)))
A25: 2 | B25: =IF(Регистрация!$D$6<A25," ",CONCATENATE(VLOOKUP(A25,Регистрация!$B$7:$N$39,3,FALSE)," ",VLOOKUP(A25,Регистрация!$B$7:$N$39,4,FALSE)," ","(",VLOOKUP(A25,Регистрация!$B$7:$N$39,11,FALSE),")")) -> Хохлова Элина (WSKF) | D25: =IF(Регистрация!$D$6<C25," ",CONCATENATE(VLOOKUP(C25,Регистрация!$B$7:$N$39,3,FALSE)," ",VLOOKUP(C25,Регистрация!$B$7:$N$39,4,FALSE)," ","(",VLOOKUP(C25,Регистрация!$B$7:$N$39,11,FALSE),")")) -> #N/A
G27: =IF(F27=0," ",CONCATENATE(VLOOKUP(F27,Регистрация!$B$7:$N$39,3,FALSE)," ",VLOOKUP(F27,Регистрация!$B$7:$N$39,4,FALSE)))
A29: 6 | B29: =IF(Регистрация!$D$6<A29," ",CONCATENATE(VLOOKUP(A29,Регистрация!$B$7:$N$39,3,FALSE)," ",VLOOKUP(A29,Регистрация!$B$7:$N$39,4,FALSE)," ","(",VLOOKUP(A29,Регистрация!$B$7:$N$39,11,FALSE),")")) -> Павлова Мария (Политех) | D29: =IF(Регистрация!$D$6<C29," ",CONCATENATE(VLOOKUP(C29,Регистрация!$B$7:$N$39,3,FALSE)," ",VLOOKUP(C29,Регистрация!$B$7:$N$39,4,FALSE)," ","(",VLOOKUP(C29,Регистрация!$B$7:$N$39,11,FALSE),")")) -> #N/A
I31: =IF(H31=0," ",CONCATENATE(VLOOKUP(H31,Регистрация!$B$7:$N$39,3,FALSE)," ",VLOOKUP(H31,Регистрация!$B$7:$N$39,4,FALSE)))
A33: 4 | B33: =IF(Регистрация!$D$6<A33," ",CONCATENATE(VLOOKUP(A33,Регистрация!$B$7:$N$39,3,FALSE)," ",VLOOKUP(A33,Регистрация!$B$7:$N$39,4,FALSE)," ","(",VLOOKUP(A33,Регистрация!$B$7:$N$39,11,FALSE),")")) -> Шайдулина Алина (Политех) | D33: =IF(Регистрация!$D$6<C33," ",CONCATENATE(VLOOKUP(C33,Регистрация!$B$7:$N$39,3,FALSE)," ",VLOOKUP(C33,Регистрация!$B$7:$N$39,4,FALSE)," ","(",VLOOKUP(C33,Регистрация!$B$7:$N$39,11,FALSE),")")) -> #N/A
G35: =IF(F35=0," ",CONCATENATE(VLOOKUP(F35,Регистрация!$B$7:$N$39,3,FALSE)," ",VLOOKUP(F35,Регистрация!$B$7:$N$39,4,FALSE))) | I35: Поединок за 3-е место
A37: 8 | B37: =IF(Регистрация!$D$6<A37," ",CONCATENATE(VLOOKUP(A37,Регистрация!$B$7:$N$39,3,FALSE)," ",VLOOKUP(A37,Регистрация!$B$7:$N$39,4,FALSE)," ","(",VLOOKUP(A37,Регистрация!$B$7:$N$39,11,FALSE),")")) | D37: =IF(Регистрация!$D$6<C37," ",CONCATENATE(VLOOKUP(C37,Регистрация!$B$7:$N$39,3,FALSE)," ",VLOOKUP(C37,Регистрация!$B$7:$N$39,4,FALSE)," ","(",VLOOKUP(C37,Регистрация!$B$7:$N$39,11,FALSE),")")) -> #N/A | H37: =IF(H15=0,0,IF(H15=F11,F19,F11)) -> 0 | I37: =IF(H37=0," ",CONCATENATE(VLOOKUP(H37,Регистрация!$B$7:$N$39,3,FALSE)," ",VLOOKUP(H37,Регистрация!$B$7:$N$39,4,FALSE)))
K38: =IF(J38=0," ",CONCATENATE(VLOOKUP(J38,Регистрация!$B$7:$N$39,3,FALSE)," ",VLOOKUP(J38,Регистрация!$B$7:$N$39,4,FALSE)))
H39: =IF(H31=0,0,IF(H31=F27,F35,F27)) -> 0 | I39: =IF(H39=0," ",CONCATENATE(VLOOKUP(H39,Регистрация!$B$7:$N$39,3,FALSE)," ",VLOOKUP(H39,Регистрация!$B$7:$N$39,4,FALSE)))
A40: Результаты
B41: Место | C41: Фамилия Имя Отчество (Регион)
A42: =J23 -> 0 | B42: 1 | C42: =IF(A42=0," ",CONCATENATE(VLOOKUP(A42,Регистрация!$B$7:$N$39,3,FALSE)," ",VLOOKUP(A42,Регистрация!$B$7:$N$39,4,FALSE)," ",VLOOKUP(A42,Регистрация!$B$7:$N$39,5,FALSE)," ","(",VLOOKUP(A42,Регистрация!$B$7:$N$39,11,FALSE),")"))
A43: =IF(J23=0,0,IF(J23=H15,H31,H15)) -> 0 | B43: 2 | C43: =IF(A43=0," ",CONCATENATE(VLOOKUP(A43,Регистрация!$B$7:$N$39,3,FALSE)," ",VLOOKUP(A43,Регистрация!$B$7:$N$39,4,FALSE)," ",VLOOKUP(A43,Регистрация!$B$7:$N$39,5,FALSE)," ","(",VLOOKUP(A43,Регистрация!$B$7:$N$39,11,FALSE),")"))
A44: =J38 -> 0 | B44: 3 | C44: =IF(A44=0," ",CONCATENATE(VLOOKUP(A44,Регистрация!$B$7:$N$39,3,FALSE)," ",VLOOKUP(A44,Регистрация!$B$7:$N$39,4,FALSE)," ",VLOOKUP(A44,Регистрация!$B$7:$N$39,5,FALSE)," ","(",VLOOKUP(A44,Регистрация!$B$7:$N$39,11,FALSE),")"))
A45: =IF(J38=0,0,IF(J38=H37,H39,H37)) -> 0 | B45: 4 | C45: =IF(A45=0," ",CONCATENATE(VLOOKUP(A45,Регистрация!$B$7:$N$39,3,FALSE)," ",VLOOKUP(A45,Регистрация!$B$7:$N$39,4,FALSE)," ",VLOOKUP(A45,Регистрация!$B$7:$N$39,5,FALSE)," ","(",VLOOKUP(A45,Регистрация!$B$7:$N$39,11,FALSE),")"))
A46: Главный судья: | J46: =Регистрация!N73 -> Цыльев В.А. С1К
A48: Главный секретарь: | J48: =Регистрация!N74 -> Орлова Е.С 3 К

Sheet 10
A1: =Регистрация!A1 -> Межмуниципальные соревнования по всестилевому каратэ "Первый старт" 27 сентября 2025 г.
A3: =Регистрация!A2 -> Вид спорта: ВСЕСТИЛЕВОЕ КАРАТЭ (номер-код вида спорта - 0900001411Я)
A5: =Регистрация!A3 -> Женщины 18 + ОК-двоеборье | D5: =Регистрация!G3 -> г. Санкт-Петербург | I5: =Регистрация!L3 -> 27 сентября 2025 | K5: =Регистрация!N3 -> 0
A7: П Р О Т О К О Л Х О Д А С О Р Е В Н О В А Н И Й
A9: 1 | B9: =IF(Регистрация!$D$6<A9," ",CONCATENATE(VLOOKUP(A9,Регистрация!$B$7:$N$39,3,FALSE)," ",VLOOKUP(A9,Регистрация!$B$7:$N$39,4,FALSE)," ","(",VLOOKUP(A9,Регистрация!$B$7:$N$39,11,FALSE),")")) -> Сугралиева Арина (Политех) | D9: =IF(Регистрация!$D$6<C9," ",CONCATENATE(VLOOKUP(C9,Регистрация!$B$7:$N$39,3,FALSE)," ",VLOOKUP(C9,Регистрация!$B$7:$N$39,4,FALSE)," ","(",VLOOKUP(C9,Регистрация!$B$7:$N$39,11,FALSE),")")) -> #N/A
F11: 9 | G11: =IF(F11=0," ",CONCATENATE(VLOOKUP(F11,Регистрация!$B$7:$N$39,3,FALSE)," ",VLOOKUP(F11,Регистрация!$B$7:$N$39,4,FALSE)))
A12: 5 | B12: =IF(Регистрация!$D$6<A12," ",CONCATENATE(VLOOKUP(A12,Регистрация!$B$7:$N$39,3,FALSE)," ",VLOOKUP(A12,Регистрация!$B$7:$N$39,4,FALSE)," ","(",VLOOKUP(A12,Регистрация!$B$7:$N$39,11,FALSE),")")) -> Носкова Александра (Политех)
D13: 9 | E13: =IF(D13=0," ",CONCATENATE(VLOOKUP(D13,Регистрация!$B$7:$N$39,3,FALSE)," ",VLOOKUP(D13,Регистрация!$B$7:$N$39,4,FALSE)))
A14: 9 | B14: =IF(Регистрация!$D$6<A14," ",CONCATENATE(VLOOKUP(A14,Регистрация!$B$7:$N$39,3,FALSE)," ",VLOOKUP(A14,Регистрация!$B$7:$N$39,4,FALSE)," ","(",VLOOKUP(A14,Регистрация!$B$7:$N$39,11,FALSE),")"))
H15: 9 | I15: =IF(H15=0," ",CONCATENATE(VLOOKUP(H15,Регистрация!$B$7:$N$39,3,FALSE)," ",VLOOKUP(H15,Регистрация!$B$7:$N$39,4,FALSE)))
A17: 3 | B17: =IF(Регистрация!$D$6<A17," ",CONCATENATE(VLOOKUP(A17,Регистрация!$B$7:$N$39,3,FALSE)," ",VLOOKUP(A17,Регистрация!$B$7:$N$39,4,FALSE)," ","(",VLOOKUP(A17,Регистрация!$B$7:$N$39,11,FALSE),")")) -> Паранина Полина (Политех) | D17: =IF(Регистрация!$D$6<C17," ",CONCATENATE(VLOOKUP(C17,Регистрация!$B$7:$N$39,3,FALSE)," ",VLOOKUP(C17,Регистрация!$B$7:$N$39,4,FALSE)," ","(",VLOOKUP(C17,Регистрация!$B$7:$N$39,11,FALSE),")")) -> #N/A
F19: 7 | G19: =IF(F19=0," ",CONCATENATE(VLOOKUP(F19,Регистрация!$B$7:$N$39,3,FALSE)," ",VLOOKUP(F19,Регистрация!$B$7:$N$39,4,FALSE)))
A21: 7 | B21: =IF(Регистрация!$D$6<A21," ",CONCATENATE(VLOOKUP(A21,Регистрация!$B$7:$N$39,3,FALSE)," ",VLOOKUP(A21,Регистрация!$B$7:$N$39,4,FALSE)," ","(",VLOOKUP(A21,Регистрация!$B$7:$N$39,11,FALSE),")")) | D21: =IF(Регистрация!$D$6<C21," ",CONCATENATE(VLOOKUP(C21,Регистрация!$B$7:$N$39,3,FALSE)," ",VLOOKUP(C21,Регистрация!$B$7:$N$39,4,FALSE)," ","(",VLOOKUP(C21,Регистрация!$B$7:$N$39,11,FALSE),")")) -> #N/A
J23: 4 | K23: =IF(J23=0," ",CONCATENATE(VLOOKUP(J23,Регистрация!$B$7:$N$39,3,FALSE)," ",VLOOKUP(J23,Регистрация!$B$7:$N$39,4,FALSE))) -> Шайдулина Алина
A25: 2 | B25: =IF(Регистрация!$D$6<A25," ",CONCATENATE(VLOOKUP(A25,Регистрация!$B$7:$N$39,3,FALSE)," ",VLOOKUP(A25,Регистрация!$B$7:$N$39,4,FALSE)," ","(",VLOOKUP(A25,Регистрация!$B$7:$N$39,11,FALSE),")")) -> Хохлова Элина (WSKF) | D25: =IF(Регистрация!$D$6<C25," ",CONCATENATE(VLOOKUP(C25,Регистрация!$B$7:$N$39,3,FALSE)," ",VLOOKUP(C25,Регистрация!$B$7:$N$39,4,FALSE)," ","(",VLOOKUP(C25,Регистрация!$B$7:$N$39,11,FALSE),")")) -> #N/A
F27: 10 | G27: =IF(F27=0," ",CONCATENATE(VLOOKUP(F27,Регистрация!$B$7:$N$39,3,FALSE)," ",VLOOKUP(F27,Регистрация!$B$7:$N$39,4,FALSE)))
A28: 6 | B28: =IF(Регистрация!$D$6<A28," ",CONCATENATE(VLOOKUP(A28,Регистрация!$B$7:$N$39,3,FALSE)," ",VLOOKUP(A28,Регистрация!$B$7:$N$39,4,FALSE)," ","(",VLOOKUP(A28,Регистрация!$B$7:$N$39,11,FALSE),")")) -> Павлова Мария (Политех)
D29: 10 | E29: =IF(D29=0," ",CONCATENATE(VLOOKUP(D29,Регистрация!$B$7:$N$39,3,FALSE)," ",VLOOKUP(D29,Регистрация!$B$7:$N$39,4,FALSE)))
A30: 10 | B30: =IF(Регистрация!$D$6<A30," ",CONCATENATE(VLOOKUP(A30,Регистрация!$B$7:$N$39,3,FALSE)," ",VLOOKUP(A30,Регистрация!$B$7:$N$39,4,FALSE)," ","(",VLOOKUP(A30,Регистрация!$B$7:$N$39,11,FALSE),")"))
H31: 4 | I31: =IF(H31=0," ",CONCATENATE(VLOOKUP(H31,Регистрация!$B$7:$N$39,3,FALSE)," ",VLOOKUP(H31,Регистрация!$B$7:$N$39,4,FALSE))) -> Шайдулина Алина
A33: 4 | B33: =IF(Регистрация!$D$6<A33," ",CONCATENATE(VLOOKUP(A33,Регистрация!$B$7:$N$39,3,FALSE)," ",VLOOKUP(A33,Регистрация!$B$7:$N$39,4,FALSE)," ","(",VLOOKUP(A33,Регистрация!$B$7:$N$39,11,FALSE),")")) -> Шайдулина Алина (Политех) | D33: =IF(Регистрация!$D$6<C33," ",CONCATENATE(VLOOKUP(C33,Регистрация!$B$7:$N$39,3,FALSE)," ",VLOOKUP(C33,Регистрация!$B$7:$N$39,4,FALSE)," ","(",VLOOKUP(C33,Регистрация!$B$7:$N$39,11,FALSE),")")) -> #N/A
F35: 4 | G35: =IF(F35=0," ",CONCATENATE(VLOOKUP(F35,Регистрация!$B$7:$N$39,3,FALSE)," ",VLOOKUP(F35,Регистрация!$B$7:$N$39,4,FALSE))) -> Шайдулина Алина | I35: Поединок за 3-е место
A37: 8 | B37: =IF(Регистрация!$D$6<A37," ",CONCATENATE(VLOOKUP(A37,Регистрация!$B$7:$N$39,3,FALSE)," ",VLOOKUP(A37,Регистрация!$B$7:$N$39,4,FALSE)," ","(",VLOOKUP(A37,Регистрация!$B$7:$N$39,11,FALSE),")")) | D37: =IF(Регистрация!$D$6<C37," ",CONCATENATE(VLOOKUP(C37,Регистрация!$B$7:$N$39,3,FALSE)," ",VLOOKUP(C37,Регистрация!$B$7:$N$39,4,FALSE)," ","(",VLOOKUP(C37,Регистрация!$B$7:$N$39,11,FALSE),")")) -> #N/A | H37: =IF(H15=0,0,IF(H15=F11,F19,F11)) -> 7 | I37: =IF(H37=0," ",CONCATENATE(VLOOKUP(H37,Регистрация!$B$7:$N$39,3,FALSE)," ",VLOOKUP(H37,Регистрация!$B$7:$N$39,4,FALSE)))
J38: 10 | K38: =IF(J38=0," ",CONCATENATE(VLOOKUP(J38,Регистрация!$B$7:$N$39,3,FALSE)," ",VLOOKUP(J38,Регистрация!$B$7:$N$39,4,FALSE)))
H39: =IF(H31=0,0,IF(H31=F27,F35,F27)) -> 10 | I39: =IF(H39=0," ",CONCATENATE(VLOOKUP(H39,Регистрация!$B$7:$N$39,3,FALSE)," ",VLOOKUP(H39,Регистрация!$B$7:$N$39,4,FALSE)))
A40: Результаты
B41: Место | C41: Фамилия Имя Отчество (Регион)
A42: =J23 -> 4 | B42: 1 | C42: =IF(A42=0," ",CONCATENATE(VLOOKUP(A42,Регистрация!$B$7:$N$39,3,FALSE)," ",VLOOKUP(A42,Регистрация!$B$7:$N$39,4,FALSE)," ",VLOOKUP(A42,Регистрация!$B$7:$N$39,5,FALSE)," ","(",VLOOKUP(A42,Регистрация!$B$7:$N$39,11,FALSE),")")) -> Шайдулина Алина Викторовна (Политех)
A43: =IF(J23=0,0,IF(J23=H15,H31,H15)) -> 9 | B43: 2 | C43: =IF(A43=0," ",CONCATENATE(VLOOKUP(A43,Регистрация!$B$7:$N$39,3,FALSE)," ",VLOOKUP(A43,Регистрация!$B$7:$N$39,4,FALSE)," ",VLOOKUP(A43,Регистрация!$B$7:$N$39,5,FALSE)," ","(",VLOOKUP(A43,Регистрация!$B$7:$N$39,11,FALSE),")")) -> ()
A44: =J38 -> 10 | B44: 3 | C44: =IF(A44=0," ",CONCATENATE(VLOOKUP(A44,Регистрация!$B$7:$N$39,3,FALSE)," ",VLOOKUP(A44,Регистрация!$B$7:$N$39,4,FALSE)," ",VLOOKUP(A44,Регистрация!$B$7:$N$39,5,FALSE)," ","(",VLOOKUP(A44,Регистрация!$B$7:$N$39,11,FALSE),")")) -> ()
A45: =IF(J38=0,0,IF(J38=H37,H39,H37)) -> 7 | B45: 4 | C45: =IF(A45=0," ",CONCATENATE(VLOOKUP(A45,Регистрация!$B$7:$N$39,3,FALSE)," ",VLOOKUP(A45,Регистрация!$B$7:$N$39,4,FALSE)," ",VLOOKUP(A45,Регистрация!$B$7:$N$39,5,FALSE)," ","(",VLOOKUP(A45,Регистрация!$B$7:$N$39,11,FALSE),")")) -> ()
A46: Главный судья: | J46: =Регистрация!N73 -> Цыльев В.А. С1К
A48: Главный секретарь: | J48: =Регистрация!N74 -> Орлова Е.С 3 К

Sheet 11
A1: =Регистрация!A1 -> Межмуниципальные соревнования по всестилевому каратэ "Первый старт" 27 сентября 2025 г.
A3: =Регистрация!A2 -> Вид спорта: ВСЕСТИЛЕВОЕ КАРАТЭ (номер-код вида спорта - 0900001411Я)
A5: =Регистрация!A3 -> Женщины 18 + ОК-двоеборье | D5: =Регистрация!G3 -> г. Санкт-Петербург | I5: =Регистрация!L3 -> 27 сентября 2025 | K5: =Регистрация!N3 -> 0
A7: П Р О Т О К О Л Х О Д А С О Р Е В Н О В А Н И Й
A9: 1 | B9: =IF(Регистрация!$D$6<A9," ",CONCATENATE(VLOOKUP(A9,Регистрация!$B$7:$N$39,3,FALSE)," ",VLOOKUP(A9,Регистрация!$B$7:$N$39,4,FALSE)," ","(",VLOOKUP(A9,Регистрация!$B$7:$N$39,11,FALSE),")")) -> Сугралиева Арина (Политех) | D9: =IF(Регистрация!$D$6<C9," ",CONCATENATE(VLOOKUP(C9,Регистрация!$B$7:$N$39,3,FALSE)," ",VLOOKUP(C9,Регистрация!$B$7:$N$39,4,FALSE)," ","(",VLOOKUP(C9,Регистрация!$B$7:$N$39,11,FALSE),")")) -> #N/A
G11: =IF(F11=0," ",CONCATENATE(VLOOKUP(F11,Регистрация!$B$7:$N$39,3,FALSE)," ",VLOOKUP(F11,Регистрация!$B$7:$N$39,4,FALSE)))
A12: 5 | B12: =IF(Регистрация!$D$6<A12," ",CONCATENATE(VLOOKUP(A12,Регистрация!$B$7:$N$39,3,FALSE)," ",VLOOKUP(A12,Регистрация!$B$7:$N$39,4,FALSE)," ","(",VLOOKUP(A12,Регистрация!$B$7:$N$39,11,FALSE),")")) -> Носкова Александра (Политех)
E13: =IF(D13=0," ",CONCATENATE(VLOOKUP(D13,Регистрация!$B$7:$N$39,3,FALSE)," ",VLOOKUP(D13,Регистрация!$B$7:$N$39,4,FALSE)))
A14: 9 | B14: =IF(Регистрация!$D$6<A14," ",CONCATENATE(VLOOKUP(A14,Регистрация!$B$7:$N$39,3,FALSE)," ",VLOOKUP(A14,Регистрация!$B$7:$N$39,4,FALSE)," ","(",VLOOKUP(A14,Регистрация!$B$7:$N$39,11,FALSE),")"))
I15: =IF(H15=0," ",CONCATENATE(VLOOKUP(H15,Регистрация!$B$7:$N$39,3,FALSE)," ",VLOOKUP(H15,Регистрация!$B$7:$N$39,4,FALSE)))
A17: 3 | B17: =IF(Регистрация!$D$6<A17," ",CONCATENATE(VLOOKUP(A17,Регистрация!$B$7:$N$39,3,FALSE)," ",VLOOKUP(A17,Регистрация!$B$7:$N$39,4,FALSE)," ","(",VLOOKUP(A17,Регистрация!$B$7:$N$39,11,FALSE),")")) -> Паранина Полина (Политех) | D17: =IF(Регистрация!$D$6<C17," ",CONCATENATE(VLOOKUP(C17,Регистрация!$B$7:$N$39,3,FALSE)," ",VLOOKUP(C17,Регистрация!$B$7:$N$39,4,FALSE)," ","(",VLOOKUP(C17,Регистрация!$B$7:$N$39,11,FALSE),")")) -> #N/A
G19: =IF(F19=0," ",CONCATENATE(VLOOKUP(F19,Регистрация!$B$7:$N$39,3,FALSE)," ",VLOOKUP(F19,Регистрация!$B$7:$N$39,4,FALSE)))
A20: 7 | B20: =IF(Регистрация!$D$6<A20," ",CONCATENATE(VLOOKUP(A20,Регистрация!$B$7:$N$39,3,FALSE)," ",VLOOKUP(A20,Регистрация!$B$7:$N$39,4,FALSE)," ","(",VLOOKUP(A20,Регистрация!$B$7:$N$39,11,FALSE),")"))
E21: =IF(D21=0," ",CONCATENATE(VLOOKUP(D21,Регистрация!$B$7:$N$39,3,FALSE)," ",VLOOKUP(D21,Регистрация!$B$7:$N$39,4,FALSE)))
A22: 11 | B22: =IF(Регистрация!$D$6<A22," ",CONCATENATE(VLOOKUP(A22,Регистрация!$B$7:$N$39,3,FALSE)," ",VLOOKUP(A22,Регистрация!$B$7:$N$39,4,FALSE)," ","(",VLOOKUP(A22,Регистрация!$B$7:$N$39,11,FALSE),")"))
K23: =IF(J23=0," ",CONCATENATE(VLOOKUP(J23,Регистрация!$B$7:$N$39,3,FALSE)," ",VLOOKUP(J23,Регистрация!$B$7:$N$39,4,FALSE)))
A25: 2 | B25: =IF(Регистрация!$D$6<A25," ",CONCATENATE(VLOOKUP(A25,Регистрация!$B$7:$N$39,3,FALSE)," ",VLOOKUP(A25,Регистрация!$B$7:$N$39,4,FALSE)," ","(",VLOOKUP(A25,Регистрация!$B$7:$N$39,11,FALSE),")")) -> Хохлова Элина (WSKF) | D25: =IF(Регистрация!$D$6<C25," ",CONCATENATE(VLOOKUP(C25,Регистрация!$B$7:$N$39,3,FALSE)," ",VLOOKUP(C25,Регистрация!$B$7:$N$39,4,FALSE)," ","(",VLOOKUP(C25,Регистрация!$B$7:$N$39,11,FALSE),")")) -> #N/A
G27: =IF(F27=0," ",CONCATENATE(VLOOKUP(F27,Регистрация!$B$7:$N$39,3,FALSE)," ",VLOOKUP(F27,Регистрация!$B$7:$N$39,4,FALSE)))
A28: 6 | B28: =IF(Регистрация!$D$6<A28," ",CONCATENATE(VLOOKUP(A28,Регистрация!$B$7:$N$39,3,FALSE)," ",VLOOKUP(A28,Регистрация!$B$7:$N$39,4,FALSE)," ","(",VLOOKUP(A28,Регистрация!$B$7:$N$39,11,FALSE),")")) -> Павлова Мария (Политех)
E29: =IF(D29=0," ",CONCATENATE(VLOOKUP(D29,Регистрация!$B$7:$N$39,3,FALSE)," ",VLOOKUP(D29,Регистрация!$B$7:$N$39,4,FALSE)))
A30: 10 | B30: =IF(Регистрация!$D$6<A30," ",CONCATENATE(VLOOKUP(A30,Регистрация!$B$7:$N$39,3,FALSE)," ",VLOOKUP(A30,Регистрация!$B$7:$N$39,4,FALSE)," ","(",VLOOKUP(A30,Регистрация!$B$7:$N$39,11,FALSE),")"))
I31: =IF(H31=0," ",CONCATENATE(VLOOKUP(H31,Регистрация!$B$7:$N$39,3,FALSE)," ",VLOOKUP(H31,Регистрация!$B$7:$N$39,4,FALSE)))
A33: 4 | B33: =IF(Регистрация!$D$6<A33," ",CONCATENATE(VLOOKUP(A33,Регистрация!$B$7:$N$39,3,FALSE)," ",VLOOKUP(A33,Регистрация!$B$7:$N$39,4,FALSE)," ","(",VLOOKUP(A33,Регистрация!$B$7:$N$39,11,FALSE),")")) -> Шайдулина Алина (Политех) | D33: =IF(Регистрация!$D$6<C33," ",CONCATENATE(VLOOKUP(C33,Регистрация!$B$7:$N$39,3,FALSE)," ",VLOOKUP(C33,Регистрация!$B$7:$N$39,4,FALSE)," ","(",VLOOKUP(C33,Регистрация!$B$7:$N$39,11,FALSE),")")) -> #N/A
G35: =IF(F35=0," ",CONCATENATE(VLOOKUP(F35,Регистрация!$B$7:$N$39,3,FALSE)," ",VLOOKUP(F35,Регистрация!$B$7:$N$39,4,FALSE))) | I35: Поединок за 3-е место
A37: 8 | B37: =IF(Регистрация!$D$6<A37," ",CONCATENATE(VLOOKUP(A37,Регистрация!$B$7:$N$39,3,FALSE)," ",VLOOKUP(A37,Регистрация!$B$7:$N$39,4,FALSE)," ","(",VLOOKUP(A37,Регистрация!$B$7:$N$39,11,FALSE),")")) | D37: =IF(Регистрация!$D$6<C37," ",CONCATENATE(VLOOKUP(C37,Регистрация!$B$7:$N$39,3,FALSE)," ",VLOOKUP(C37,Регистрация!$B$7:$N$39,4,FALSE)," ","(",VLOOKUP(C37,Регистрация!$B$7:$N$39,11,FALSE),")")) -> #N/A | H37: =IF(H15=0,0,IF(H15=F11,F19,F11)) -> 0 | I37: =IF(H37=0," ",CONCATENATE(VLOOKUP(H37,Регистрация!$B$7:$N$39,3,FALSE)," ",VLOOKUP(H37,Регистрация!$B$7:$N$39,4,FALSE)))
K38: =IF(J38=0," ",CONCATENATE(VLOOKUP(J38,Регистрация!$B$7:$N$39,3,FALSE)," ",VLOOKUP(J38,Регистрация!$B$7:$N$39,4,FALSE)))
H39: =IF(H31=0,0,IF(H31=F27,F35,F27)) -> 0 | I39: =IF(H39=0," ",CONCATENATE(VLOOKUP(H39,Регистрация!$B$7:$N$39,3,FALSE)," ",VLOOKUP(H39,Регистрация!$B$7:$N$39,4,FALSE)))
A40: Результаты
B41: Место | C41: Фамилия Имя Отчество (Регион)
A42: =J23 -> 0 | B42: 1 | C42: =IF(A42=0," ",CONCATENATE(VLOOKUP(A42,Регистрация!$B$7:$N$39,3,FALSE)," ",VLOOKUP(A42,Регистрация!$B$7:$N$39,4,FALSE)," ",VLOOKUP(A42,Регистрация!$B$7:$N$39,5,FALSE)," ","(",VLOOKUP(A42,Регистрация!$B$7:$N$39,11,FALSE),")"))
A43: =IF(J23=0,0,IF(J23=H15,H31,H15)) -> 0 | B43: 2 | C43: =IF(A43=0," ",CONCATENATE(VLOOKUP(A43,Регистрация!$B$7:$N$39,3,FALSE)," ",VLOOKUP(A43,Регистрация!$B$7:$N$39,4,FALSE)," ",VLOOKUP(A43,Регистрация!$B$7:$N$39,5,FALSE)," ","(",VLOOKUP(A43,Регистрация!$B$7:$N$39,11,FALSE),")"))
A44: =J38 -> 0 | B44: 3 | C44: =IF(A44=0," ",CONCATENATE(VLOOKUP(A44,Регистрация!$B$7:$N$39,3,FALSE)," ",VLOOKUP(A44,Регистрация!$B$7:$N$39,4,FALSE)," ",VLOOKUP(A44,Регистрация!$B$7:$N$39,5,FALSE)," ","(",VLOOKUP(A44,Регистрация!$B$7:$N$39,11,FALSE),")"))
A45: =IF(J38=0,0,IF(J38=H37,H39,H37)) -> 0 | B45: 4 | C45: =IF(A45=0," ",CONCATENATE(VLOOKUP(A45,Регистрация!$B$7:$N$39,3,FALSE)," ",VLOOKUP(A45,Регистрация!$B$7:$N$39,4,FALSE)," ",VLOOKUP(A45,Регистрация!$B$7:$N$39,5,FALSE)," ","(",VLOOKUP(A45,Регистрация!$B$7:$N$39,11,FALSE),")"))
A46: Главный судья: | J46: =Регистрация!N73 -> Цыльев В.А. С1К
A48: Главный секретарь: | J48: =Регистрация!N74 -> Орлова Е.С 3 К

Sheet 12
A1: =Регистрация!A1 -> Межмуниципальные соревнования по всестилевому каратэ "Первый старт" 27 сентября 2025 г.
A3: =Регистрация!A2 -> Вид спорта: ВСЕСТИЛЕВОЕ КАРАТЭ (номер-код вида спорта - 0900001411Я)
A5: =Регистрация!A3 -> Женщины 18 + ОК-двоеборье | D5: =Регистрация!G3 -> г. Санкт-Петербург | I5: =Регистрация!L3 -> 27 сентября 2025 | K5: =Регистрация!N3 -> 0
A7: П Р О Т О К О Л Х О Д А С О Р Е В Н О В А Н И Й
A9: 1 | B9: =IF(Регистрация!$D$6<A9," ",CONCATENATE(VLOOKUP(A9,Регистрация!$B$7:$N$39,3,FALSE)," ",VLOOKUP(A9,Регистрация!$B$7:$N$39,4,FALSE)," ","(",VLOOKUP(A9,Регистрация!$B$7:$N$39,11,FALSE),")")) -> Сугралиева Арина (Политех) | D9: =IF(Регистрация!$D$6<C9," ",CONCATENATE(VLOOKUP(C9,Регистрация!$B$7:$N$39,3,FALSE)," ",VLOOKUP(C9,Регистрация!$B$7:$N$39,4,FALSE)," ","(",VLOOKUP(C9,Регистрация!$B$7:$N$39,11,FALSE),")")) -> #N/A
G11: =IF(F11=0," ",CONCATENATE(VLOOKUP(F11,Регистрация!$B$7:$N$39,3,FALSE)," ",VLOOKUP(F11,Регистрация!$B$7:$N$39,4,FALSE)))
A12: 5 | B12: =IF(Регистрация!$D$6<A12," ",CONCATENATE(VLOOKUP(A12,Регистрация!$B$7:$N$39,3,FALSE)," ",VLOOKUP(A12,Регистрация!$B$7:$N$39,4,FALSE)," ","(",VLOOKUP(A12,Регистрация!$B$7:$N$39,11,FALSE),")")) -> Носкова Александра (Политех)
E13: =IF(D13=0," ",CONCATENATE(VLOOKUP(D13,Регистрация!$B$7:$N$39,3,FALSE)," ",VLOOKUP(D13,Регистрация!$B$7:$N$39,4,FALSE)))
A14: 9 | B14: =IF(Регистрация!$D$6<A14," ",CONCATENATE(VLOOKUP(A14,Регистрация!$B$7:$N$39,3,FALSE)," ",VLOOKUP(A14,Регистрация!$B$7:$N$39,4,FALSE)," ","(",VLOOKUP(A14,Регистрация!$B$7:$N$39,11,FALSE),")"))
I15: =IF(H15=0," ",CONCATENATE(VLOOKUP(H15,Регистрация!$B$7:$N$39,3,FALSE)," ",VLOOKUP(H15,Регистрация!$B$7:$N$39,4,FALSE)))
A17: 3 | B17: =IF(Регистрация!$D$6<A17," ",CONCATENATE(VLOOKUP(A17,Регистрация!$B$7:$N$39,3,FALSE)," ",VLOOKUP(A17,Регистрация!$B$7:$N$39,4,FALSE)," ","(",VLOOKUP(A17,Регистрация!$B$7:$N$39,11,FALSE),")")) -> Паранина Полина (Политех) | D17: =IF(Регистрация!$D$6<C17," ",CONCATENATE(VLOOKUP(C17,Регистрация!$B$7:$N$39,3,FALSE)," ",VLOOKUP(C17,Регистрация!$B$7:$N$39,4,FALSE)," ","(",VLOOKUP(C17,Регистрация!$B$7:$N$39,11,FALSE),")")) -> #N/A
G19: =IF(F19=0," ",CONCATENATE(VLOOKUP(F19,Регистрация!$B$7:$N$39,3,FALSE)," ",VLOOKUP(F19,Регистрация!$B$7:$N$39,4,FALSE)))
A20: 7 | B20: =IF(Регистрация!$D$6<A20," ",CONCATENATE(VLOOKUP(A20,Регистрация!$B$7:$N$39,3,FALSE)," ",VLOOKUP(A20,Регистрация!$B$7:$N$39,4,FALSE)," ","(",VLOOKUP(A20,Регистрация!$B$7:$N$39,11,FALSE),")"))
E21: =IF(D21=0," ",CONCATENATE(VLOOKUP(D21,Регистрация!$B$7:$N$39,3,FALSE)," ",VLOOKUP(D21,Регистрация!$B$7:$N$39,4,FALSE)))
A22: 11 | B22: =IF(Регистрация!$D$6<A22," ",CONCATENATE(VLOOKUP(A22,Регистрация!$B$7:$N$39,3,FALSE)," ",VLOOKUP(A22,Регистрация!$B$7:$N$39,4,FALSE)," ","(",VLOOKUP(A22,Регистрация!$B$7:$N$39,11,FALSE),")"))
K23: =IF(J23=0," ",CONCATENATE(VLOOKUP(J23,Регистрация!$B$7:$N$39,3,FALSE)," ",VLOOKUP(J23,Регистрация!$B$7:$N$39,4,FALSE)))
A25: 2 | B25: =IF(Регистрация!$D$6<A25," ",CONCATENATE(VLOOKUP(A25,Регистрация!$B$7:$N$39,3,FALSE)," ",VLOOKUP(A25,Регистрация!$B$7:$N$39,4,FALSE)," ","(",VLOOKUP(A25,Регистрация!$B$7:$N$39,11,FALSE),")")) -> Хохлова Элина (WSKF) | D25: =IF(Регистрация!$D$6<C25," ",CONCATENATE(VLOOKUP(C25,Регистрация!$B$7:$N$39,3,FALSE)," ",VLOOKUP(C25,Регистрация!$B$7:$N$39,4,FALSE)," ","(",VLOOKUP(C25,Регистрация!$B$7:$N$39,11,FALSE),")")) -> #N/A
G27: =IF(F27=0," ",CONCATENATE(VLOOKUP(F27,Регистрация!$B$7:$N$39,3,FALSE)," ",VLOOKUP(F27,Регистрация!$B$7:$N$39,4,FALSE)))
A28: 6 | B28: =IF(Регистрация!$D$6<A28," ",CONCATENATE(VLOOKUP(A28,Регистрация!$B$7:$N$39,3,FALSE)," ",VLOOKUP(A28,Регистрация!$B$7:$N$39,4,FALSE)," ","(",VLOOKUP(A28,Регистрация!$B$7:$N$39,11,FALSE),")")) -> Павлова Мария (Политех)
E29: =IF(D29=0," ",CONCATENATE(VLOOKUP(D29,Регистрация!$B$7:$N$39,3,FALSE)," ",VLOOKUP(D29,Регистрация!$B$7:$N$39,4,FALSE)))
A30: 10 | B30: =IF(Регистрация!$D$6<A30," ",CONCATENATE(VLOOKUP(A30,Регистрация!$B$7:$N$39,3,FALSE)," ",VLOOKUP(A30,Регистрация!$B$7:$N$39,4,FALSE)," ","(",VLOOKUP(A30,Регистрация!$B$7:$N$39,11,FALSE),")"))
I31: =IF(H31=0," ",CONCATENATE(VLOOKUP(H31,Регистрация!$B$7:$N$39,3,FALSE)," ",VLOOKUP(H31,Регистрация!$B$7:$N$39,4,FALSE)))
A33: 4 | B33: =IF(Регистрация!$D$6<A33," ",CONCATENATE(VLOOKUP(A33,Регистрация!$B$7:$N$39,3,FALSE)," ",VLOOKUP(A33,Регистрация!$B$7:$N$39,4,FALSE)," ","(",VLOOKUP(A33,Регистрация!$B$7:$N$39,11,FALSE),")")) -> Шайдулина Алина (Политех) | D33: =IF(Регистрация!$D$6<C33," ",CONCATENATE(VLOOKUP(C33,Регистрация!$B$7:$N$39,3,FALSE)," ",VLOOKUP(C33,Регистрация!$B$7:$N$39,4,FALSE)," ","(",VLOOKUP(C33,Регистрация!$B$7:$N$39,11,FALSE),")")) -> #N/A
G35: =IF(F35=0," ",CONCATENATE(VLOOKUP(F35,Регистрация!$B$7:$N$39,3,FALSE)," ",VLOOKUP(F35,Регистрация!$B$7:$N$39,4,FALSE))) | I35: Поединок за 3-е место
A36: 8 | B36: =IF(Регистрация!$D$6<A36," ",CONCATENATE(VLOOKUP(A36,Регистрация!$B$7:$N$39,3,FALSE)," ",VLOOKUP(A36,Регистрация!$B$7:$N$39,4,FALSE)," ","(",VLOOKUP(A36,Регистрация!$B$7:$N$39,11,FALSE),")"))
E37: =IF(D37=0," ",CONCATENATE(VLOOKUP(D37,Регистрация!$B$7:$N$39,3,FALSE)," ",VLOOKUP(D37,Регистрация!$B$7:$N$39,4,FALSE))) | H37: =IF(H15=0,0,IF(H15=F11,F19,F11)) -> 0 | I37: =IF(H37=0," ",CONCATENATE(VLOOKUP(H37,Регистрация!$B$7:$N$39,3,FALSE)," ",VLOOKUP(H37,Регистрация!$B$7:$N$39,4,FALSE)))
A38: 12 | B38: =IF(Регистрация!$D$6<A38," ",CONCATENATE(VLOOKUP(A38,Регистрация!$B$7:$N$39,3,FALSE)," ",VLOOKUP(A38,Регистрация!$B$7:$N$39,4,FALSE)," ","(",VLOOKUP(A38,Регистрация!$B$7:$N$39,11,FALSE),")")) | K38: =IF(J38=0," ",CONCATENATE(VLOOKUP(J38,Регистрация!$B$7:$N$39,3,FALSE)," ",VLOOKUP(J38,Регистрация!$B$7:$N$39,4,FALSE)))
H39: =IF(H31=0,0,IF(H31=F27,F35,F27)) -> 0 | I39: =IF(H39=0," ",CONCATENATE(VLOOKUP(H39,Регистрация!$B$7:$N$39,3,FALSE)," ",VLOOKUP(H39,Регистрация!$B$7:$N$39,4,FALSE)))
A40: Результаты
B41: Место | C41: Фамилия Имя Отчество (Регион)
A42: =J23 -> 0 | B42: 1 | C42: =IF(A42=0," ",CONCATENATE(VLOOKUP(A42,Регистрация!$B$7:$N$39,3,FALSE)," ",VLOOKUP(A42,Регистрация!$B$7:$N$39,4,FALSE)," ",VLOOKUP(A42,Регистрация!$B$7:$N$39,5,FALSE)," ","(",VLOOKUP(A42,Регистрация!$B$7:$N$39,11,FALSE),")"))
A43: =IF(J23=0,0,IF(J23=H15,H31,H15)) -> 0 | B43: 2 | C43: =IF(A43=0," ",CONCATENATE(VLOOKUP(A43,Регистрация!$B$7:$N$39,3,FALSE)," ",VLOOKUP(A43,Регистрация!$B$7:$N$39,4,FALSE)," ",VLOOKUP(A43,Регистрация!$B$7:$N$39,5,FALSE)," ","(",VLOOKUP(A43,Регистрация!$B$7:$N$39,11,FALSE),")"))
A44: =J38 -> 0 | B44: 3 | C44: =IF(A44=0," ",CONCATENATE(VLOOKUP(A44,Регистрация!$B$7:$N$39,3,FALSE)," ",VLOOKUP(A44,Регистрация!$B$7:$N$39,4,FALSE)," ",VLOOKUP(A44,Регистрация!$B$7:$N$39,5,FALSE)," ","(",VLOOKUP(A44,Регистрация!$B$7:$N$39,11,FALSE),")"))
A45: =IF(J38=0,0,IF(J38=H37,H39,H37)) -> 0 | B45: 4 | C45: =IF(A45=0," ",CONCATENATE(VLOOKUP(A45,Регистрация!$B$7:$N$39,3,FALSE)," ",VLOOKUP(A45,Регистрация!$B$7:$N$39,4,FALSE)," ",VLOOKUP(A45,Регистрация!$B$7:$N$39,5,FALSE)," ","(",VLOOKUP(A45,Регистрация!$B$7:$N$39,11,FALSE),")"))
A46: Главный судья: | J46: =Регистрация!N73 -> Цыльев В.А. С1К
A48: Главный секретарь: | J48: =Регистрация!N74 -> Орлова Е.С 3 К

Sheet 13
A1: =Регистрация!A1 -> Межмуниципальные соревнования по всестилевому каратэ "Первый старт" 27 сентября 2025 г.
A3: =Регистрация!A2 -> Вид спорта: ВСЕСТИЛЕВОЕ КАРАТЭ (номер-код вида спорта - 0900001411Я)
A5: =Регистрация!A3 -> Женщины 18 + ОК-двоеборье | D5: =Регистрация!G3 -> г. Санкт-Петербург | I5: =Регистрация!L3 -> 27 сентября 2025 | K5: =Регистрация!N3 -> 0
A7: П Р О Т О К О Л Х О Д А С О Р Е В Н О В А Н И Й
A9: 1 | B9: =IF(Регистрация!$D$6<A9," ",CONCATENATE(VLOOKUP(A9,Регистрация!$B$7:$N$39,3,FALSE)," ",VLOOKUP(A9,Регистрация!$B$7:$N$39,4,FALSE)," ","(",VLOOKUP(A9,Регистрация!$B$7:$N$39,11,FALSE),")")) -> Сугралиева Арина (Политех) | D9: =IF(Регистрация!$D$6<C9," ",CONCATENATE(VLOOKUP(C9,Регистрация!$B$7:$N$39,3,FALSE)," ",VLOOKUP(C9,Регистрация!$B$7:$N$39,4,FALSE)," ","(",VLOOKUP(C9,Регистрация!$B$7:$N$39,11,FALSE),")")) -> #N/A
G11: =IF(F11=0," ",CONCATENATE(VLOOKUP(F11,Регистрация!$B$7:$N$39,3,FALSE)," ",VLOOKUP(F11,Регистрация!$B$7:$N$39,4,FALSE)))
A12: 5 | B12: =IF(Регистрация!$D$6<A12," ",CONCATENATE(VLOOKUP(A12,Регистрация!$B$7:$N$39,3,FALSE)," ",VLOOKUP(A12,Регистрация!$B$7:$N$39,4,FALSE)," ","(",VLOOKUP(A12,Регистрация!$B$7:$N$39,11,FALSE),")")) -> Носкова Александра (Политех)
E13: =IF(D13=0," ",CONCATENATE(VLOOKUP(D13,Регистрация!$B$7:$N$39,3,FALSE)," ",VLOOKUP(D13,Регистрация!$B$7:$N$39,4,FALSE)))
A14: 9 | B14: =IF(Регистрация!$D$6<A14," ",CONCATENATE(VLOOKUP(A14,Регистрация!$B$7:$N$39,3,FALSE)," ",VLOOKUP(A14,Регистрация!$B$7:$N$39,4,FALSE)," ","(",VLOOKUP(A14,Регистрация!$B$7:$N$39,11,FALSE),")"))
I15: =IF(H15=0," ",CONCATENATE(VLOOKUP(H15,Регистрация!$B$7:$N$39,3,FALSE)," ",VLOOKUP(H15,Регистрация!$B$7:$N$39,4,FALSE)))
A16: 3 | B16: =IF(Регистрация!$D$6<A16," ",CONCATENATE(VLOOKUP(A16,Регистрация!$B$7:$N$39,3,FALSE)," ",VLOOKUP(A16,Регистрация!$B$7:$N$39,4,FALSE)," ","(",VLOOKUP(A16,Регистрация!$B$7:$N$39,11,FALSE),")")) -> Паранина Полина (Политех)
E17: =IF(D17=0," ",CONCATENATE(VLOOKUP(D17,Регистрация!$B$7:$N$39,3,FALSE)," ",VLOOKUP(D17,Регистрация!$B$7:$N$39,4,FALSE)))
A18: 11 | B18: =IF(Регистрация!$D$6<A18," ",CONCATENATE(VLOOKUP(A18,Регистрация!$B$7:$N$39,3,FALSE)," ",VLOOKUP(A18,Регистрация!$B$7:$N$39,4,FALSE)," ","(",VLOOKUP(A18,Регистрация!$B$7:$N$39,11,FALSE),")"))
G19: =IF(F19=0," ",CONCATENATE(VLOOKUP(F19,Регистрация!$B$7:$N$39,3,FALSE)," ",VLOOKUP(F19,Регистрация!$B$7:$N$39,4,FALSE)))
A20: 7 | B20: =IF(Регистрация!$D$6<A20," ",CONCATENATE(VLOOKUP(A20,Регистрация!$B$7:$N$39,3,FALSE)," ",VLOOKUP(A20,Регистрация!$B$7:$N$39,4,FALSE)," ","(",VLOOKUP(A20,Регистрация!$B$7:$N$39,11,FALSE),")"))
E21: =IF(D21=0," ",CONCATENATE(VLOOKUP(D21,Регистрация!$B$7:$N$39,3,FALSE)," ",VLOOKUP(D21,Регистрация!$B$7:$N$39,4,FALSE)))
A22: 13 | B22: =IF(Регистрация!$D$6<A22," ",CONCATENATE(VLOOKUP(A22,Регистрация!$B$7:$N$39,3,FALSE)," ",VLOOKUP(A22,Регистрация!$B$7:$N$39,4,FALSE)," ","(",VLOOKUP(A22,Регистрация!$B$7:$N$39,11,FALSE),")"))
K23: =IF(J23=0," ",CONCATENATE(VLOOKUP(J23,Регистрация!$B$7:$N$39,3,FALSE)," ",VLOOKUP(J23,Регистрация!$B$7:$N$39,4,FALSE)))
A25: 2 | B25: =IF(Регистрация!$D$6<A25," ",CONCATENATE(VLOOKUP(A25,Регистрация!$B$7:$N$39,3,FALSE)," ",VLOOKUP(A25,Регистрация!$B$7:$N$39,4,FALSE)," ","(",VLOOKUP(A25,Регистрация!$B$7:$N$39,11,FALSE),")")) -> Хохлова Элина (WSKF) | D25: =IF(Регистрация!$D$6<C25," ",CONCATENATE(VLOOKUP(C25,Регистрация!$B$7:$N$39,3,FALSE)," ",VLOOKUP(C25,Регистрация!$B$7:$N$39,4,FALSE)," ","(",VLOOKUP(C25,Регистрация!$B$7:$N$39,11,FALSE),")")) -> #N/A
G27: =IF(F27=0," ",CONCATENATE(VLOOKUP(F27,Регистрация!$B$7:$N$39,3,FALSE)," ",VLOOKUP(F27,Регистрация!$B$7:$N$39,4,FALSE)))
A28: 6 | B28: =IF(Регистрация!$D$6<A28," ",CONCATENATE(VLOOKUP(A28,Регистрация!$B$7:$N$39,3,FALSE)," ",VLOOKUP(A28,Регистрация!$B$7:$N$39,4,FALSE)," ","(",VLOOKUP(A28,Регистрация!$B$7:$N$39,11,FALSE),")")) -> Павлова Мария (Политех)
E29: =IF(D29=0," ",CONCATENATE(VLOOKUP(D29,Регистрация!$B$7:$N$39,3,FALSE)," ",VLOOKUP(D29,Регистрация!$B$7:$N$39,4,FALSE)))
A30: 10 | B30: =IF(Регистрация!$D$6<A30," ",CONCATENATE(VLOOKUP(A30,Регистрация!$B$7:$N$39,3,FALSE)," ",VLOOKUP(A30,Регистрация!$B$7:$N$39,4,FALSE)," ","(",VLOOKUP(A30,Регистрация!$B$7:$N$39,11,FALSE),")"))
I31: =IF(H31=0," ",CONCATENATE(VLOOKUP(H31,Регистрация!$B$7:$N$39,3,FALSE)," ",VLOOKUP(H31,Регистрация!$B$7:$N$39,4,FALSE)))
A33: 4 | B33: =IF(Регистрация!$D$6<A33," ",CONCATENATE(VLOOKUP(A33,Регистрация!$B$7:$N$39,3,FALSE)," ",VLOOKUP(A33,Регистрация!$B$7:$N$39,4,FALSE)," ","(",VLOOKUP(A33,Регистрация!$B$7:$N$39,11,FALSE),")")) -> Шайдулина Алина (Политех) | D33: =IF(Регистрация!$D$6<C33," ",CONCATENATE(VLOOKUP(C33,Регистрация!$B$7:$N$39,3,FALSE)," ",VLOOKUP(C33,Регистрация!$B$7:$N$39,4,FALSE)," ","(",VLOOKUP(C33,Регистрация!$B$7:$N$39,11,FALSE),")")) -> #N/A
G35: =IF(F35=0," ",CONCATENATE(VLOOKUP(F35,Регистрация!$B$7:$N$39,3,FALSE)," ",VLOOKUP(F35,Регистрация!$B$7:$N$39,4,FALSE))) | I35: Поединок за 3-е место
A36: 8 | B36: =IF(Регистрация!$D$6<A36," ",CONCATENATE(VLOOKUP(A36,Регистрация!$B$7:$N$39,3,FALSE)," ",VLOOKUP(A36,Регистрация!$B$7:$N$39,4,FALSE)," ","(",VLOOKUP(A36,Регистрация!$B$7:$N$39,11,FALSE),")"))
E37: =IF(D37=0," ",CONCATENATE(VLOOKUP(D37,Регистрация!$B$7:$N$39,3,FALSE)," ",VLOOKUP(D37,Регистрация!$B$7:$N$39,4,FALSE))) | H37: =IF(H15=0,0,IF(H15=F11,F19,F11)) -> 0 | I37: =IF(H37=0," ",CONCATENATE(VLOOKUP(H37,Регистрация!$B$7:$N$39,3,FALSE)," ",VLOOKUP(H37,Регистрация!$B$7:$N$39,4,FALSE)))
